Workbook

Sheet Panell_de_control
A1: PANELL DE CONTROL · OBSERVACIONS MP12 2026-27
A2: =TEXT(TODAY(),"DD/MM/YYYY") -> 27/06/2026 | G2: Setmanes des de l'inici del mòdul: | H2: =IFERROR(MAX(0,ROUND((MIN(TODAY(),Calendari!$C$6)-Calendari!$B$2)/7,1)),0) -> 0
A4: RESUM PER GRUP
A5: Grup | B5: Observacions totals | C5: Obs. / setmana | D5: Alumnes registrats | E5: Alumnes sense obs. | F5: % amb saldo positiu | G5: % amb saldo negatiu | H5: Alumnes total
A6: Grup A | B6: =MAX(0,COUNTA(SMIX2AT!$A:$A)-1) -> 0 | C6: =IFERROR(B6/$H$2,0) -> 0 | D6: =COUNTIF(Alumnes_A!$B$3:$B$40,"<>") -> 0 | E6: =COUNTIFS(Alumnes_A!$O$3:$O$40,0,Alumnes_A!$B$3:$B$40,"<>") -> 0 | F6: =IFERROR(COUNTIFS(Alumnes_A!$N$3:$N$40,">"&0,Alumnes_A!$B$3:$B$40,"<>")/COUNTIF(Alumnes_A!$B$3:$B$40,"<>"),0) -> 0 | G6: =IFERROR(COUNTIFS(Alumnes_A!$N$3:$N$40,"<"&0,Alumnes_A!$B$3:$B$40,"<>")/COUNTIF(Alumnes_A!$B$3:$B$40,"<>"),0) -> 0 | H6: =COUNTA(Alumnes_A!$A$3:$A$40) -> 22
A7: Grup B | B7: =MAX(0,COUNTA(SMIX2BT!$A:$A)-1) -> 0 | C7: =IFERROR(B7/$H$2,0) -> 0 | D7: =COUNTIF(Alumnes_B!$B$3:$B$40,"<>") -> 0 | E7: =COUNTIFS(Alumnes_B!$O$3:$O$40,0,Alumnes_B!$B$3:$B$40,"<>") -> 0 | F7: =IFERROR(COUNTIFS(Alumnes_B!$N$3:$N$40,">"&0,Alumnes_B!$B$3:$B$40,"<>")/COUNTIF(Alumnes_B!$B$3:$B$40,"<>"),0) -> 0 | G7: =IFERROR(COUNTIFS(Alumnes_B!$N$3:$N$40,"<"&0,Alumnes_B!$B$3:$B$40,"<>")/COUNTIF(Alumnes_B!$B$3:$B$40,"<>"),0) -> 0 | H7: =COUNTA(Alumnes_B!$A$3:$A$40) -> 23
A8: Grup C | B8: =MAX(0,COUNTA(SMIX2CT!$A:$A)-1) -> 31 | C8: =IFERROR(B8/$H$2,0) -> 0 | D8: =COUNTIF(Alumnes_C!$B$3:$B$40,"<>") -> 17 | E8: =COUNTIFS(Alumnes_C!$O$3:$O$40,0,Alumnes_C!$B$3:$B$40,"<>") -> 17 | F8: =IFERROR(COUNTIFS(Alumnes_C!$N$3:$N$40,">"&0,Alumnes_C!$B$3:$B$40,"<>")/COUNTIF(Alumnes_C!$B$3:$B$40,"<>"),0) -> 0.41176471 | G8: =IFERROR(COUNTIFS(Alumnes_C!$N$3:$N$40,"<"&0,Alumnes_C!$B$3:$B$40,"<>")/COUNTIF(Alumnes_C!$B$3:$B$40,"<>"),0) -> 0.52941176 | H8: =COUNTA(Alumnes_C!$A$3:$A$40) -> 23
A9: Grup D | B9: =MAX(0,COUNTA(SMIX2DT!$A:$A)-1) -> 19 | C9: =IFERROR(B9/$H$2,0) -> 0 | D9: =COUNTIF(Alumnes_D!$B$3:$B$40,"<>") -> 13 | E9: =COUNTIFS(Alumnes_D!$O$3:$O$40,0,Alumnes_D!$B$3:$B$40,"<>") -> 13 | F9: =IFERROR(COUNTIFS(Alumnes_D!$N$3:$N$40,">"&0,Alumnes_D!$B$3:$B$40,"<>")/COUNTIF(Alumnes_D!$B$3:$B$40,"<>"),0) -> 0.61538462 | G9: =IFERROR(COUNTIFS(Alumnes_D!$N$3:$N$40,"<"&0,Alumnes_D!$B$3:$B$40,"<>")/COUNTIF(Alumnes_D!$B$3:$B$40,"<>"),0) -> 0.23076923 | H9: =COUNTA(Alumnes_D!$A$3:$A$40) -> 21
A10: TOTAL MÒDUL | B10: =B6+B7+B8+B9 -> 50 | C10: =IFERROR(B10/$H$2,0) -> 0 | D10: =D6+D7+D8+D9 -> 30
A12: PROFESSORS
A13: Introduïu el nom de cada professor exactament com apareix al formulari:
A14: Professor | B14: Observ. totals | C14: Grup A | D14: Grup B | E14: Grup C | F14: Grup D
A15: Pere Arnau | B15: =IF(A15="",0,C15+D15+E15+F15) -> 26 | C15: =IF(A15="",0,COUNTIF(SMIX2AT!$C:$C,A15)) -> 0 | D15: =IF(A15="",0,COUNTIF(SMIX2BT!$C:$C,A15)) -> 0 | E15: =IF(A15="",0,COUNTIF(SMIX2CT!$C:$C,A15)) -> 12 | F15: =IF(A15="",0,COUNTIF(SMIX2DT!$C:$C,A15)) -> 14
A16: Roger Ferrándiz | B16: =IF(A16="",0,C16+D16+E16+F16) -> 19 | C16: =IF(A16="",0,COUNTIF(SMIX2AT!$C:$C,A16)) -> 0 | D16: =IF(A16="",0,COUNTIF(SMIX2BT!$C:$C,A16)) -> 0 | E16: =IF(A16="",0,COUNTIF(SMIX2CT!$C:$C,A16)) -> 19 | F16: =IF(A16="",0,COUNTIF(SMIX2DT!$C:$C,A16)) -> 0
A17: Joan Botella | B17: =IF(A17="",0,C17+D17+E17+F17) -> 5 | C17: =IF(A17="",0,COUNTIF(SMIX2AT!$C:$C,A17)) -> 0 | D17: =IF(A17="",0,COUNTIF(SMIX2BT!$C:$C,A17)) -> 0 | E17: =IF(A17="",0,COUNTIF(SMIX2CT!$C:$C,A17)) -> 0 | F17: =IF(A17="",0,COUNTIF(SMIX2DT!$C:$C,A17)) -> 5
B18: =IF(A18="",0,C18+D18+E18+F18) -> 0 | C18: =IF(A18="",0,COUNTIF(SMIX2AT!$C:$C,A18)) -> 0 | D18: =IF(A18="",0,COUNTIF(SMIX2BT!$C:$C,A18)) -> 0 | E18: =IF(A18="",0,COUNTIF(SMIX2CT!$C:$C,A18)) -> 0 | F18: =IF(A18="",0,COUNTIF(SMIX2DT!$C:$C,A18)) -> 0
B19: =IF(A19="",0,C19+D19+E19+F19) -> 0 | C19: =IF(A19="",0,COUNTIF(SMIX2AT!$C:$C,A19)) -> 0 | D19: =IF(A19="",0,COUNTIF(SMIX2BT!$C:$C,A19)) -> 0 | E19: =IF(A19="",0,COUNTIF(SMIX2CT!$C:$C,A19)) -> 0 | F19: =IF(A19="",0,COUNTIF(SMIX2DT!$C:$C,A19)) -> 0
B20: =IF(A20="",0,C20+D20+E20+F20) -> 0 | C20: =IF(A20="",0,COUNTIF(SMIX2AT!$C:$C,A20)) -> 0 | D20: =IF(A20="",0,COUNTIF(SMIX2BT!$C:$C,A20)) -> 0 | E20: =IF(A20="",0,COUNTIF(SMIX2CT!$C:$C,A20)) -> 0 | F20: =IF(A20="",0,COUNTIF(SMIX2DT!$C:$C,A20)) -> 0
A21: Professor amb MÉS observacions: | D21: =IFERROR(INDEX(A15:A20,MATCH(MAX(B15:B20),B15:B20,0))&" ("&MAX(B15:B20)&" obs.)","—") -> Pere Arnau (26 obs.)
A22: Professor amb MENYS observacions: | D22: =IFERROR(INDEX(A15:A20,MATCH(minifs(B15:B20,B15:B20,">"&0),B15:B20,0))&" ("&minifs(B15:B20,B15:B20,">"&0)&" obs.)","—") -> —
A24: TOP 3 ALUMNES PER GRUP (basat en la puntuació neta acumulada)
A25: Grup | B25: # | C25: 🏆 Positiu #1 | D25: Punt. neta | E25: ⚠️ Negatiu #1 | F25: Punt. neta
A26: Grup A | B26: 1 | C26: =IFERROR(IF(LARGE(Alumnes_A!$N$3:$N$40,1)>0,INDEX(Alumnes_A!$A$3:$A$40,MATCH(LARGE(Alumnes_A!$N$3:$N$40,1),Alumnes_A!$N$3:$N$40,0)),"—"),"—") -> — | D26: =IFERROR(IF(LARGE(Alumnes_A!$N$3:$N$40,1)>0,LARGE(Alumnes_A!$N$3:$N$40,1),"—"),"—") -> — | E26: =IFERROR(IF(SMALL(Alumnes_A!$N$3:$N$40,1)<0,INDEX(Alumnes_A!$A$3:$A$40,MATCH(SMALL(Alumnes_A!$N$3:$N$40,1),Alumnes_A!$N$3:$N$40,0)),"—"),"—") -> — | F26: =IFERROR(IF(SMALL(Alumnes_A!$N$3:$N$40,1)<0,SMALL(Alumnes_A!$N$3:$N$40,1),"—"),"—") -> —
B27: 2 | C27: =IFERROR(IF(LARGE(Alumnes_A!$N$3:$N$40,2)>0,INDEX(Alumnes_A!$A$3:$A$40,MATCH(LARGE(Alumnes_A!$N$3:$N$40,2),Alumnes_A!$N$3:$N$40,0)),"—"),"—") -> — | D27: =IFERROR(IF(LARGE(Alumnes_A!$N$3:$N$40,2)>0,LARGE(Alumnes_A!$N$3:$N$40,2),"—"),"—") -> — | E27: =IFERROR(IF(SMALL(Alumnes_A!$N$3:$N$40,2)<0,INDEX(Alumnes_A!$A$3:$A$40,MATCH(SMALL(Alumnes_A!$N$3:$N$40,2),Alumnes_A!$N$3:$N$40,0)),"—"),"—") -> — | F27: =IFERROR(IF(SMALL(Alumnes_A!$N$3:$N$40,2)<0,SMALL(Alumnes_A!$N$3:$N$40,2),"—"),"—") -> —
B28: 3 | C28: =IFERROR(IF(LARGE(Alumnes_A!$N$3:$N$40,3)>0,INDEX(Alumnes_A!$A$3:$A$40,MATCH(LARGE(Alumnes_A!$N$3:$N$40,3),Alumnes_A!$N$3:$N$40,0)),"—"),"—") -> — | D28: =IFERROR(IF(LARGE(Alumnes_A!$N$3:$N$40,3)>0,LARGE(Alumnes_A!$N$3:$N$40,3),"—"),"—") -> — | E28: =IFERROR(IF(SMALL(Alumnes_A!$N$3:$N$40,3)<0,INDEX(Alumnes_A!$A$3:$A$40,MATCH(SMALL(Alumnes_A!$N$3:$N$40,3),Alumnes_A!$N$3:$N$40,0)),"—"),"—") -> — | F28: =IFERROR(IF(SMALL(Alumnes_A!$N$3:$N$40,3)<0,SMALL(Alumnes_A!$N$3:$N$40,3),"—"),"—") -> —
A29: Grup B | B29: 1 | C29: =IFERROR(IF(LARGE(Alumnes_B!$N$3:$N$40,1)>0,INDEX(Alumnes_B!$A$3:$A$40,MATCH(LARGE(Alumnes_B!$N$3:$N$40,1),Alumnes_B!$N$3:$N$40,0)),"—"),"—") -> — | D29: =IFERROR(IF(LARGE(Alumnes_B!$N$3:$N$40,1)>0,LARGE(Alumnes_B!$N$3:$N$40,1),"—"),"—") -> — | E29: =IFERROR(IF(SMALL(Alumnes_B!$N$3:$N$40,1)<0,INDEX(Alumnes_B!$A$3:$A$40,MATCH(SMALL(Alumnes_B!$N$3:$N$40,1),Alumnes_B!$N$3:$N$40,0)),"—"),"—") -> — | F29: =IFERROR(IF(SMALL(Alumnes_B!$N$3:$N$40,1)<0,SMALL(Alumnes_B!$N$3:$N$40,1),"—"),"—") -> —
B30: 2 | C30: =IFERROR(IF(LARGE(Alumnes_B!$N$3:$N$40,2)>0,INDEX(Alumnes_B!$A$3:$A$40,MATCH(LARGE(Alumnes_B!$N$3:$N$40,2),Alumnes_B!$N$3:$N$40,0)),"—"),"—") -> — | D30: =IFERROR(IF(LARGE(Alumnes_B!$N$3:$N$40,2)>0,LARGE(Alumnes_B!$N$3:$N$40,2),"—"),"—") -> — | E30: =IFERROR(IF(SMALL(Alumnes_B!$N$3:$N$40,2)<0,INDEX(Alumnes_B!$A$3:$A$40,MATCH(SMALL(Alumnes_B!$N$3:$N$40,2),Alumnes_B!$N$3:$N$40,0)),"—"),"—") -> — | F30: =IFERROR(IF(SMALL(Alumnes_B!$N$3:$N$40,2)<0,SMALL(Alumnes_B!$N$3:$N$40,2),"—"),"—") -> —
B31: 3 | C31: =IFERROR(IF(LARGE(Alumnes_B!$N$3:$N$40,3)>0,INDEX(Alumnes_B!$A$3:$A$40,MATCH(LARGE(Alumnes_B!$N$3:$N$40,3),Alumnes_B!$N$3:$N$40,0)),"—"),"—") -> — | D31: =IFERROR(IF(LARGE(Alumnes_B!$N$3:$N$40,3)>0,LARGE(Alumnes_B!$N$3:$N$40,3),"—"),"—") -> — | E31: =IFERROR(IF(SMALL(Alumnes_B!$N$3:$N$40,3)<0,INDEX(Alumnes_B!$A$3:$A$40,MATCH(SMALL(Alumnes_B!$N$3:$N$40,3),Alumnes_B!$N$3:$N$40,0)),"—"),"—") -> — | F31: =IFERROR(IF(SMALL(Alumnes_B!$N$3:$N$40,3)<0,SMALL(Alumnes_B!$N$3:$N$40,3),"—"),"—") -> —
A32: Grup C | B32: 1 | C32: =IFERROR(IF(LARGE(Alumnes_C!$N$3:$N$40,1)>0,INDEX(Alumnes_C!$A$3:$A$40,MATCH(LARGE(Alumnes_C!$N$3:$N$40,1),Alumnes_C!$N$3:$N$40,0)),"—"),"—") -> Alexis Martínez Vaca | D32: =IFERROR(IF(LARGE(Alumnes_C!$N$3:$N$40,1)>0,LARGE(Alumnes_C!$N$3:$N$40,1),"—"),"—") -> 4 | E32: =IFERROR(IF(SMALL(Alumnes_C!$N$3:$N$40,1)<0,INDEX(Alumnes_C!$A$3:$A$40,MATCH(SMALL(Alumnes_C!$N$3:$N$40,1),Alumnes_C!$N$3:$N$40,0)),"—"),"—") -> Izan Malagón Martinez | F32: =IFERROR(IF(SMALL(Alumnes_C!$N$3:$N$40,1)<0,SMALL(Alumnes_C!$N$3:$N$40,1),"—"),"—") -> -2
B33: 2 | C33: =IFERROR(IF(LARGE(Alumnes_C!$N$3:$N$40,2)>0,INDEX(Alumnes_C!$A$3:$A$40,MATCH(LARGE(Alumnes_C!$N$3:$N$40,2),Alumnes_C!$N$3:$N$40,0)),"—"),"—") -> Albert Gálvez García | D33: =IFERROR(IF(LARGE(Alumnes_C!$N$3:$N$40,2)>0,LARGE(Alumnes_C!$N$3:$N$40,2),"—"),"—") -> 3 | E33: =IFERROR(IF(SMALL(Alumnes_C!$N$3:$N$40,2)<0,INDEX(Alumnes_C!$A$3:$A$40,MATCH(SMALL(Alumnes_C!$N$3:$N$40,2),Alumnes_C!$N$3:$N$40,0)),"—"),"—") -> Izan Malagón Martinez | F33: =IFERROR(IF(SMALL(Alumnes_C!$N$3:$N$40,2)<0,SMALL(Alumnes_C!$N$3:$N$40,2),"—"),"—") -> -2
B34: 3 | C34: =IFERROR(IF(LARGE(Alumnes_C!$N$3:$N$40,3)>0,INDEX(Alumnes_C!$A$3:$A$40,MATCH(LARGE(Alumnes_C!$N$3:$N$40,3),Alumnes_C!$N$3:$N$40,0)),"—"),"—") -> Aitor Fernández Bernabé | D34: =IFERROR(IF(LARGE(Alumnes_C!$N$3:$N$40,3)>0,LARGE(Alumnes_C!$N$3:$N$40,3),"—"),"—") -> 2 | E34: =IFERROR(IF(SMALL(Alumnes_C!$N$3:$N$40,3)<0,INDEX(Alumnes_C!$A$3:$A$40,MATCH(SMALL(Alumnes_C!$N$3:$N$40,3),Alumnes_C!$N$3:$N$40,0)),"—"),"—") -> Oussama El Idrissi | F34: =IFERROR(IF(SMALL(Alumnes_C!$N$3:$N$40,3)<0,SMALL(Alumnes_C!$N$3:$N$40,3),"—"),"—") -> -1
A35: Grup D | B35: 1 | C35: =IFERROR(IF(LARGE(Alumnes_D!$N$3:$N$40,1)>0,INDEX(Alumnes_D!$A$3:$A$40,MATCH(LARGE(Alumnes_D!$N$3:$N$40,1),Alumnes_D!$N$3:$N$40,0)),"—"),"—") -> Ibai Aroca Hinojo | D35: =IFERROR(IF(LARGE(Alumnes_D!$N$3:$N$40,1)>0,LARGE(Alumnes_D!$N$3:$N$40,1),"—"),"—") -> 3 | E35: =IFERROR(IF(SMALL(Alumnes_D!$N$3:$N$40,1)<0,INDEX(Alumnes_D!$A$3:$A$40,MATCH(SMALL(Alumnes_D!$N$3:$N$40,1),Alumnes_D!$N$3:$N$40,0)),"—"),"—") -> Aleix Morante Polo | F35: =IFERROR(IF(SMALL(Alumnes_D!$N$3:$N$40,1)<0,SMALL(Alumnes_D!$N$3:$N$40,1),"—"),"—") -> -3
B36: 2 | C36: =IFERROR(IF(LARGE(Alumnes_D!$N$3:$N$40,2)>0,INDEX(Alumnes_D!$A$3:$A$40,MATCH(LARGE(Alumnes_D!$N$3:$N$40,2),Alumnes_D!$N$3:$N$40,0)),"—"),"—") -> Ibai Aroca Hinojo | D36: =IFERROR(IF(LARGE(Alumnes_D!$N$3:$N$40,2)>0,LARGE(Alumnes_D!$N$3:$N$40,2),"—"),"—") -> 3 | E36: =IFERROR(IF(SMALL(Alumnes_D!$N$3:$N$40,2)<0,INDEX(Alumnes_D!$A$3:$A$40,MATCH(SMALL(Alumnes_D!$N$3:$N$40,2),Alumnes_D!$N$3:$N$40,0)),"—"),"—") -> Adam Bakal El Abbassi | F36: =IFERROR(IF(SMALL(Alumnes_D!$N$3:$N$40,2)<0,SMALL(Alumnes_D!$N$3:$N$40,2),"—"),"—") -> -2
B37: 3 | C37: =IFERROR(IF(LARGE(Alumnes_D!$N$3:$N$40,3)>0,INDEX(Alumnes_D!$A$3:$A$40,MATCH(LARGE(Alumnes_D!$N$3:$N$40,3),Alumnes_D!$N$3:$N$40,0)),"—"),"—") -> Raúl Pérez Barba | D37: =IFERROR(IF(LARGE(Alumnes_D!$N$3:$N$40,3)>0,LARGE(Alumnes_D!$N$3:$N$40,3),"—"),"—") -> 2 | E37: =IFERROR(IF(SMALL(Alumnes_D!$N$3:$N$40,3)<0,INDEX(Alumnes_D!$A$3:$A$40,MATCH(SMALL(Alumnes_D!$N$3:$N$40,3),Alumnes_D!$N$3:$N$40,0)),"—"),"—") -> Unai Zarzuelo Bernardino | F37: =IFERROR(IF(SMALL(Alumnes_D!$N$3:$N$40,3)<0,SMALL(Alumnes_D!$N$3:$N$40,3),"—"),"—") -> -1
A39: INDICADORS ADDICIONALS
A40: Valoració mitjana per observació (tot el mòdul) | F40: =IFERROR((SUMIF(SMIX2AT!$I$2:$I$200,"<>",SMIX2AT!$I$2:$I$200)+SUMIF(SMIX2BT!$I$2:$I$200,"<>",SMIX2BT!$I$2:$I$200)+SUMIF(SMIX2CT!$I$2:$I$200,"<>",SMIX2CT!$I$2:$I$200)+SUMIF(SMIX2DT!$I$2:$I$200,"<>",SMIX2DT!$I$2:$I$200))/(MAX(0,COUNTA(SMIX2AT!$A:$A)-1)+MAX(0,COUNTA(SMIX2BT!$A:$A)-1)+MAX(0,COUNTA(SMIX2CT!$A:$A)-1)+MAX(0,COUNTA(SMIX2DT!$A:$A)-1)),"Sense dades") -> 0.2
A41: Observacions positives (valoració > 0) al mòdul | F41: =COUNTIF(SMIX2AT!$I$2:$I$200,">"&0)+COUNTIF(SMIX2BT!$I$2:$I$200,">"&0)+COUNTIF(SMIX2CT!$I$2:$I$200,">"&0)+COUNTIF(SMIX2DT!$I$2:$I$200,">"&0) -> 19
A42: Observacions negatives (valoració < 0) al mòdul | F42: =COUNTIF(SMIX2AT!$I$2:$I$200,"<"&0)+COUNTIF(SMIX2BT!$I$2:$I$200,"<"&0)+COUNTIF(SMIX2CT!$I$2:$I$200,"<"&0)+COUNTIF(SMIX2DT!$I$2:$I$200,"<"&0) -> 21
A43: Observacions neutres (valoració = 0) al mòdul | F43: =COUNTIF(SMIX2CT!$I$2:$I$200,0)+COUNTIF(SMIX2DT!$I$2:$I$200,0)+COUNTIF(SMIX2AT!$I$2:$I$200,0)+COUNTIF(SMIX2BT!$I$2:$I$200,0) -> 756
A44: Alumnes amb multiplicador final > 1.0 (impacte positiu) | F44: =COUNTIF(Alumnes_A!$N$3:$N$40,">"&0)+COUNTIF(Alumnes_B!$N$3:$N$40,">"&0)+COUNTIF(Alumnes_C!$N$3:$N$40,">"&0)+COUNTIF(Alumnes_D!$N$3:$N$40,">"&0) -> 15
...

Sheet SMIX2AT
A1: Marca de temps | B1: Adreça electrònica | C1: Professor | D1: Alumne | E1: Competència transversal observada | F1: Valoració | G1: Descripció breu del comportament observat | H1: Quin projecte estem fent? | I1: Puntuació
I2: =IF(F2="",0,IFERROR(VALUE(LEFT(TRIM(F2),FIND(" ",TRIM(F2))-1)),0)) -> 0
I3: =IF(F3="",0,IFERROR(VALUE(LEFT(TRIM(F3),FIND(" ",TRIM(F3))-1)),0)) -> 0
I4: =IF(F4="",0,IFERROR(VALUE(LEFT(TRIM(F4),FIND(" ",TRIM(F4))-1)),0)) -> 0
I5: =IF(F5="",0,IFERROR(VALUE(LEFT(TRIM(F5),FIND(" ",TRIM(F5))-1)),0)) -> 0
I6: =IF(F6="",0,IFERROR(VALUE(LEFT(TRIM(F6),FIND(" ",TRIM(F6))-1)),0)) -> 0
I7: =IF(F7="",0,IFERROR(VALUE(LEFT(TRIM(F7),FIND(" ",TRIM(F7))-1)),0)) -> 0
I8: =IF(F8="",0,IFERROR(VALUE(LEFT(TRIM(F8),FIND(" ",TRIM(F8))-1)),0)) -> 0
I9: =IF(F9="",0,IFERROR(VALUE(LEFT(TRIM(F9),FIND(" ",TRIM(F9))-1)),0)) -> 0
I10: =IF(F10="",0,IFERROR(VALUE(LEFT(TRIM(F10),FIND(" ",TRIM(F10))-1)),0)) -> 0
I11: =IF(F11="",0,IFERROR(VALUE(LEFT(TRIM(F11),FIND(" ",TRIM(F11))-1)),0)) -> 0
I12: =IF(F12="",0,IFERROR(VALUE(LEFT(TRIM(F12),FIND(" ",TRIM(F12))-1)),0)) -> 0
I13: =IF(F13="",0,IFERROR(VALUE(LEFT(TRIM(F13),FIND(" ",TRIM(F13))-1)),0)) -> 0
... I200: =IF(F200="",0,IFERROR(VALUE(LEFT(TRIM(F200),FIND(" ",TRIM(F200))-1)),0)) -> 0

Sheet Alumnes_A
A1: SMIX2AT
A2: Nom i cognoms | B2: Cognoms, nom | C2: correu | D2: P1-obs | E2: P1-balanç | F2: P2-obs | G2: P2-balanç | H2: P3-obs | I2: P3-balanç | J2: P4-obs | K2: P4-balanç | L2: P5-obs | M2: P5-balanç | N2: Puntuació neta | O2: Total observacions
A3: Walid Akayour Stitou Tassi | C3: akayour.stitou.tassi.walid@alumnat.copernic.cat | D3: =IF($B3="",0,COUNTIFS(SMIX2AT!$D$2:$D$200,$B3,SMIX2AT!$H$2:$H$200,"P1")) -> 0 | E3: =MAX(0.5,MIN(1.5,1+IF($B3="",0,SUMPRODUCT((SMIX2AT!$D$2:$D$200=$B3)*(SMIX2AT!$H$2:$H$200="P1")*SMIX2AT!$I$2:$I$200*0.01)))) -> 1 | F3: =IF($B3="",0,COUNTIFS(SMIX2AT!$D$2:$D$200,$B3,SMIX2AT!$H$2:$H$200,"P2")) -> 0 | G3: =MAX(0.5,MIN(1.5,1+IF($B3="",0,SUMPRODUCT((SMIX2AT!$D$2:$D$200=$B3)*(SMIX2AT!$H$2:$H$200="P2")*SMIX2AT!$I$2:$I$200*0.01)))) -> 1 | H3: =IF($B3="",0,COUNTIFS(SMIX2AT!$D$2:$D$200,$B3,SMIX2AT!$H$2:$H$200,"P3")) -> 0 | I3: =MAX(0.5,MIN(1.5,1+IF($B3="",0,SUMPRODUCT((SMIX2AT!$D$2:$D$200=$B3)*(SMIX2AT!$H$2:$H$200="P3")*SMIX2AT!$I$2:$I$200*0.01)))) -> 1 | J3: =IF($B3="",0,COUNTIFS(SMIX2AT!$D$2:$D$200,$B3,SMIX2AT!$H$2:$H$200,"P4")) -> 0 | K3: =MAX(0.5,MIN(1.5,1+IF($B3="",0,SUMPRODUCT((SMIX2AT!$D$2:$D$200=$B3)*(SMIX2AT!$H$2:$H$200="P4")*SMIX2AT!$I$2:$I$200*0.01)))) -> 1 | L3: =IF($B3="",0,COUNTIFS(SMIX2AT!$D$2:$D$200,$B3,SMIX2AT!$H$2:$H$200,"P5")) -> 0 | M3: =MAX(0.5,MIN(1.5,1+IF($B3="",0,SUMPRODUCT((SMIX2AT!$D$2:$D$200=$B3)*(SMIX2AT!$H$2:$H$200="P5")*SMIX2AT!$I$2:$I$200*0.01)))) -> 1 | N3: =IF($B3="",0,IFERROR(SUMPRODUCT((SMIX2AT!$D$2:$D$200=$B3)*SMIX2AT!$I$2:$I$200),0)) -> 0 | O3: =D3+F3+H3+J3+L3 -> 0
A4: Ariadna Barros Picazo | C4: abarros@alumnat.copernic.cat | D4: =IF($B4="",0,COUNTIFS(SMIX2AT!$D$2:$D$200,$B4,SMIX2AT!$H$2:$H$200,"P1")) -> 0 | E4: =MAX(0.5,MIN(1.5,1+IF($B4="",0,SUMPRODUCT((SMIX2AT!$D$2:$D$200=$B4)*(SMIX2AT!$H$2:$H$200="P1")*SMIX2AT!$I$2:$I$200*0.01)))) -> 1 | F4: =IF($B4="",0,COUNTIFS(SMIX2AT!$D$2:$D$200,$B4,SMIX2AT!$H$2:$H$200,"P2")) -> 0 | G4: =MAX(0.5,MIN(1.5,1+IF($B4="",0,SUMPRODUCT((SMIX2AT!$D$2:$D$200=$B4)*(SMIX2AT!$H$2:$H$200="P2")*SMIX2AT!$I$2:$I$200*0.01)))) -> 1 | H4: =IF($B4="",0,COUNTIFS(SMIX2AT!$D$2:$D$200,$B4,SMIX2AT!$H$2:$H$200,"P3")) -> 0 | I4: =MAX(0.5,MIN(1.5,1+IF($B4="",0,SUMPRODUCT((SMIX2AT!$D$2:$D$200=$B4)*(SMIX2AT!$H$2:$H$200="P3")*SMIX2AT!$I$2:$I$200*0.01)))) -> 1 | J4: =IF($B4="",0,COUNTIFS(SMIX2AT!$D$2:$D$200,$B4,SMIX2AT!$H$2:$H$200,"P4")) -> 0 | K4: =MAX(0.5,MIN(1.5,1+IF($B4="",0,SUMPRODUCT((SMIX2AT!$D$2:$D$200=$B4)*(SMIX2AT!$H$2:$H$200="P4")*SMIX2AT!$I$2:$I$200*0.01)))) -> 1 | L4: =IF($B4="",0,COUNTIFS(SMIX2AT!$D$2:$D$200,$B4,SMIX2AT!$H$2:$H$200,"P5")) -> 0 | M4: =MAX(0.5,MIN(1.5,1+IF($B4="",0,SUMPRODUCT((SMIX2AT!$D$2:$D$200=$B4)*(SMIX2AT!$H$2:$H$200="P5")*SMIX2AT!$I$2:$I$200*0.01)))) -> 1 | N4: =IF($B4="",0,IFERROR(SUMPRODUCT((SMIX2AT!$D$2:$D$200=$B4)*SMIX2AT!$I$2:$I$200),0)) -> 0 | O4: =D4+F4+H4+J4+L4 -> 0
A5: Adrián Cañero García | C5: acanero@alumnat.copernic.cat | D5: =IF($B5="",0,COUNTIFS(SMIX2AT!$D$2:$D$200,$B5,SMIX2AT!$H$2:$H$200,"P1")) -> 0 | E5: =MAX(0.5,MIN(1.5,1+IF($B5="",0,SUMPRODUCT((SMIX2AT!$D$2:$D$200=$B5)*(SMIX2AT!$H$2:$H$200="P1")*SMIX2AT!$I$2:$I$200*0.01)))) -> 1 | F5: =IF($B5="",0,COUNTIFS(SMIX2AT!$D$2:$D$200,$B5,SMIX2AT!$H$2:$H$200,"P2")) -> 0 | G5: =MAX(0.5,MIN(1.5,1+IF($B5="",0,SUMPRODUCT((SMIX2AT!$D$2:$D$200=$B5)*(SMIX2AT!$H$2:$H$200="P2")*SMIX2AT!$I$2:$I$200*0.01)))) -> 1 | H5: =IF($B5="",0,COUNTIFS(SMIX2AT!$D$2:$D$200,$B5,SMIX2AT!$H$2:$H$200,"P3")) -> 0 | I5: =MAX(0.5,MIN(1.5,1+IF($B5="",0,SUMPRODUCT((SMIX2AT!$D$2:$D$200=$B5)*(SMIX2AT!$H$2:$H$200="P3")*SMIX2AT!$I$2:$I$200*0.01)))) -> 1 | J5: =IF($B5="",0,COUNTIFS(SMIX2AT!$D$2:$D$200,$B5,SMIX2AT!$H$2:$H$200,"P4")) -> 0 | K5: =MAX(0.5,MIN(1.5,1+IF($B5="",0,SUMPRODUCT((SMIX2AT!$D$2:$D$200=$B5)*(SMIX2AT!$H$2:$H$200="P4")*SMIX2AT!$I$2:$I$200*0.01)))) -> 1 | L5: =IF($B5="",0,COUNTIFS(SMIX2AT!$D$2:$D$200,$B5,SMIX2AT!$H$2:$H$200,"P5")) -> 0 | M5: =MAX(0.5,MIN(1.5,1+IF($B5="",0,SUMPRODUCT((SMIX2AT!$D$2:$D$200=$B5)*(SMIX2AT!$H$2:$H$200="P5")*SMIX2AT!$I$2:$I$200*0.01)))) -> 1 | N5: =IF($B5="",0,IFERROR(SUMPRODUCT((SMIX2AT!$D$2:$D$200=$B5)*SMIX2AT!$I$2:$I$200),0)) -> 0 | O5: =D5+F5+H5+J5+L5 -> 0
A6: Izan Cantero Perez | C6: icantero@alumnat.copernic.cat | D6: =IF($B6="",0,COUNTIFS(SMIX2AT!$D$2:$D$200,$B6,SMIX2AT!$H$2:$H$200,"P1")) -> 0 | E6: =MAX(0.5,MIN(1.5,1+IF($B6="",0,SUMPRODUCT((SMIX2AT!$D$2:$D$200=$B6)*(SMIX2AT!$H$2:$H$200="P1")*SMIX2AT!$I$2:$I$200*0.01)))) -> 1 | F6: =IF($B6="",0,COUNTIFS(SMIX2AT!$D$2:$D$200,$B6,SMIX2AT!$H$2:$H$200,"P2")) -> 0 | G6: =MAX(0.5,MIN(1.5,1+IF($B6="",0,SUMPRODUCT((SMIX2AT!$D$2:$D$200=$B6)*(SMIX2AT!$H$2:$H$200="P2")*SMIX2AT!$I$2:$I$200*0.01)))) -> 1 | H6: =IF($B6="",0,COUNTIFS(SMIX2AT!$D$2:$D$200,$B6,SMIX2AT!$H$2:$H$200,"P3")) -> 0 | I6: =MAX(0.5,MIN(1.5,1+IF($B6="",0,SUMPRODUCT((SMIX2AT!$D$2:$D$200=$B6)*(SMIX2AT!$H$2:$H$200="P3")*SMIX2AT!$I$2:$I$200*0.01)))) -> 1 | J6: =IF($B6="",0,COUNTIFS(SMIX2AT!$D$2:$D$200,$B6,SMIX2AT!$H$2:$H$200,"P4")) -> 0 | K6: =MAX(0.5,MIN(1.5,1+IF($B6="",0,SUMPRODUCT((SMIX2AT!$D$2:$D$200=$B6)*(SMIX2AT!$H$2:$H$200="P4")*SMIX2AT!$I$2:$I$200*0.01)))) -> 1 | L6: =IF($B6="",0,COUNTIFS(SMIX2AT!$D$2:$D$200,$B6,SMIX2AT!$H$2:$H$200,"P5")) -> 0 | M6: =MAX(0.5,MIN(1.5,1+IF($B6="",0,SUMPRODUCT((SMIX2AT!$D$2:$D$200=$B6)*(SMIX2AT!$H$2:$H$200="P5")*SMIX2AT!$I$2:$I$200*0.01)))) -> 1 | N6: =IF($B6="",0,IFERROR(SUMPRODUCT((SMIX2AT!$D$2:$D$200=$B6)*SMIX2AT!$I$2:$I$200),0)) -> 0 | O6: =D6+F6+H6+J6+L6 -> 0
A7: John Chévez Paniagua | C7: jchevez@alumnat.copernic.cat | D7: =IF($B7="",0,COUNTIFS(SMIX2AT!$D$2:$D$200,$B7,SMIX2AT!$H$2:$H$200,"P1")) -> 0 | E7: =MAX(0.5,MIN(1.5,1+IF($B7="",0,SUMPRODUCT((SMIX2AT!$D$2:$D$200=$B7)*(SMIX2AT!$H$2:$H$200="P1")*SMIX2AT!$I$2:$I$200*0.01)))) -> 1 | F7: =IF($B7="",0,COUNTIFS(SMIX2AT!$D$2:$D$200,$B7,SMIX2AT!$H$2:$H$200,"P2")) -> 0 | G7: =MAX(0.5,MIN(1.5,1+IF($B7="",0,SUMPRODUCT((SMIX2AT!$D$2:$D$200=$B7)*(SMIX2AT!$H$2:$H$200="P2")*SMIX2AT!$I$2:$I$200*0.01)))) -> 1 | H7: =IF($B7="",0,COUNTIFS(SMIX2AT!$D$2:$D$200,$B7,SMIX2AT!$H$2:$H$200,"P3")) -> 0 | I7: =MAX(0.5,MIN(1.5,1+IF($B7="",0,SUMPRODUCT((SMIX2AT!$D$2:$D$200=$B7)*(SMIX2AT!$H$2:$H$200="P3")*SMIX2AT!$I$2:$I$200*0.01)))) -> 1 | J7: =IF($B7="",0,COUNTIFS(SMIX2AT!$D$2:$D$200,$B7,SMIX2AT!$H$2:$H$200,"P4")) -> 0 | K7: =MAX(0.5,MIN(1.5,1+IF($B7="",0,SUMPRODUCT((SMIX2AT!$D$2:$D$200=$B7)*(SMIX2AT!$H$2:$H$200="P4")*SMIX2AT!$I$2:$I$200*0.01)))) -> 1 | L7: =IF($B7="",0,COUNTIFS(SMIX2AT!$D$2:$D$200,$B7,SMIX2AT!$H$2:$H$200,"P5")) -> 0 | M7: =MAX(0.5,MIN(1.5,1+IF($B7="",0,SUMPRODUCT((SMIX2AT!$D$2:$D$200=$B7)*(SMIX2AT!$H$2:$H$200="P5")*SMIX2AT!$I$2:$I$200*0.01)))) -> 1 | N7: =IF($B7="",0,IFERROR(SUMPRODUCT((SMIX2AT!$D$2:$D$200=$B7)*SMIX2AT!$I$2:$I$200),0)) -> 0 | O7: =D7+F7+H7+J7+L7 -> 0
A8: Anouar Daih Seraiti | C8: adaih@alumnat.copernic.cat | D8: =IF($B8="",0,COUNTIFS(SMIX2AT!$D$2:$D$200,$B8,SMIX2AT!$H$2:$H$200,"P1")) -> 0 | E8: =MAX(0.5,MIN(1.5,1+IF($B8="",0,SUMPRODUCT((SMIX2AT!$D$2:$D$200=$B8)*(SMIX2AT!$H$2:$H$200="P1")*SMIX2AT!$I$2:$I$200*0.01)))) -> 1 | F8: =IF($B8="",0,COUNTIFS(SMIX2AT!$D$2:$D$200,$B8,SMIX2AT!$H$2:$H$200,"P2")) -> 0 | G8: =MAX(0.5,MIN(1.5,1+IF($B8="",0,SUMPRODUCT((SMIX2AT!$D$2:$D$200=$B8)*(SMIX2AT!$H$2:$H$200="P2")*SMIX2AT!$I$2:$I$200*0.01)))) -> 1 | H8: =IF($B8="",0,COUNTIFS(SMIX2AT!$D$2:$D$200,$B8,SMIX2AT!$H$2:$H$200,"P3")) -> 0 | I8: =MAX(0.5,MIN(1.5,1+IF($B8="",0,SUMPRODUCT((SMIX2AT!$D$2:$D$200=$B8)*(SMIX2AT!$H$2:$H$200="P3")*SMIX2AT!$I$2:$I$200*0.01)))) -> 1 | J8: =IF($B8="",0,COUNTIFS(SMIX2AT!$D$2:$D$200,$B8,SMIX2AT!$H$2:$H$200,"P4")) -> 0 | K8: =MAX(0.5,MIN(1.5,1+IF($B8="",0,SUMPRODUCT((SMIX2AT!$D$2:$D$200=$B8)*(SMIX2AT!$H$2:$H$200="P4")*SMIX2AT!$I$2:$I$200*0.01)))) -> 1 | L8: =IF($B8="",0,COUNTIFS(SMIX2AT!$D$2:$D$200,$B8,SMIX2AT!$H$2:$H$200,"P5")) -> 0 | M8: =MAX(0.5,MIN(1.5,1+IF($B8="",0,SUMPRODUCT((SMIX2AT!$D$2:$D$200=$B8)*(SMIX2AT!$H$2:$H$200="P5")*SMIX2AT!$I$2:$I$200*0.01)))) -> 1 | N8: =IF($B8="",0,IFERROR(SUMPRODUCT((SMIX2AT!$D$2:$D$200=$B8)*SMIX2AT!$I$2:$I$200),0)) -> 0 | O8: =D8+F8+H8+J8+L8 -> 0
A9: Iker Espinosa Bujardon | C9: iespinosa@alumnat.copernic.cat | D9: =IF($B9="",0,COUNTIFS(SMIX2AT!$D$2:$D$200,$B9,SMIX2AT!$H$2:$H$200,"P1")) -> 0 | E9: =MAX(0.5,MIN(1.5,1+IF($B9="",0,SUMPRODUCT((SMIX2AT!$D$2:$D$200=$B9)*(SMIX2AT!$H$2:$H$200="P1")*SMIX2AT!$I$2:$I$200*0.01)))) -> 1 | F9: =IF($B9="",0,COUNTIFS(SMIX2AT!$D$2:$D$200,$B9,SMIX2AT!$H$2:$H$200,"P2")) -> 0 | G9: =MAX(0.5,MIN(1.5,1+IF($B9="",0,SUMPRODUCT((SMIX2AT!$D$2:$D$200=$B9)*(SMIX2AT!$H$2:$H$200="P2")*SMIX2AT!$I$2:$I$200*0.01)))) -> 1 | H9: =IF($B9="",0,COUNTIFS(SMIX2AT!$D$2:$D$200,$B9,SMIX2AT!$H$2:$H$200,"P3")) -> 0 | I9: =MAX(0.5,MIN(1.5,1+IF($B9="",0,SUMPRODUCT((SMIX2AT!$D$2:$D$200=$B9)*(SMIX2AT!$H$2:$H$200="P3")*SMIX2AT!$I$2:$I$200*0.01)))) -> 1 | J9: =IF($B9="",0,COUNTIFS(SMIX2AT!$D$2:$D$200,$B9,SMIX2AT!$H$2:$H$200,"P4")) -> 0 | K9: =MAX(0.5,MIN(1.5,1+IF($B9="",0,SUMPRODUCT((SMIX2AT!$D$2:$D$200=$B9)*(SMIX2AT!$H$2:$H$200="P4")*SMIX2AT!$I$2:$I$200*0.01)))) -> 1 | L9: =IF($B9="",0,COUNTIFS(SMIX2AT!$D$2:$D$200,$B9,SMIX2AT!$H$2:$H$200,"P5")) -> 0 | M9: =MAX(0.5,MIN(1.5,1+IF($B9="",0,SUMPRODUCT((SMIX2AT!$D$2:$D$200=$B9)*(SMIX2AT!$H$2:$H$200="P5")*SMIX2AT!$I$2:$I$200*0.01)))) -> 1 | N9: =IF($B9="",0,IFERROR(SUMPRODUCT((SMIX2AT!$D$2:$D$200=$B9)*SMIX2AT!$I$2:$I$200),0)) -> 0 | O9: =D9+F9+H9+J9+L9 -> 0
A10: Walid Farah Temsamani-Zebzabi | C10: wfarah@alumnat.copernic.cat | D10: =IF($B10="",0,COUNTIFS(SMIX2AT!$D$2:$D$200,$B10,SMIX2AT!$H$2:$H$200,"P1")) -> 0 | E10: =MAX(0.5,MIN(1.5,1+IF($B10="",0,SUMPRODUCT((SMIX2AT!$D$2:$D$200=$B10)*(SMIX2AT!$H$2:$H$200="P1")*SMIX2AT!$I$2:$I$200*0.01)))) -> 1 | F10: =IF($B10="",0,COUNTIFS(SMIX2AT!$D$2:$D$200,$B10,SMIX2AT!$H$2:$H$200,"P2")) -> 0 | G10: =MAX(0.5,MIN(1.5,1+IF($B10="",0,SUMPRODUCT((SMIX2AT!$D$2:$D$200=$B10)*(SMIX2AT!$H$2:$H$200="P2")*SMIX2AT!$I$2:$I$200*0.01)))) -> 1 | H10: =IF($B10="",0,COUNTIFS(SMIX2AT!$D$2:$D$200,$B10,SMIX2AT!$H$2:$H$200,"P3")) -> 0 | I10: =MAX(0.5,MIN(1.5,1+IF($B10="",0,SUMPRODUCT((SMIX2AT!$D$2:$D$200=$B10)*(SMIX2AT!$H$2:$H$200="P3")*SMIX2AT!$I$2:$I$200*0.01)))) -> 1 | J10: =IF($B10="",0,COUNTIFS(SMIX2AT!$D$2:$D$200,$B10,SMIX2AT!$H$2:$H$200,"P4")) -> 0 | K10: =MAX(0.5,MIN(1.5,1+IF($B10="",0,SUMPRODUCT((SMIX2AT!$D$2:$D$200=$B10)*(SMIX2AT!$H$2:$H$200="P4")*SMIX2AT!$I$2:$I$200*0.01)))) -> 1 | L10: =IF($B10="",0,COUNTIFS(SMIX2AT!$D$2:$D$200,$B10,SMIX2AT!$H$2:$H$200,"P5")) -> 0 | M10: =MAX(0.5,MIN(1.5,1+IF($B10="",0,SUMPRODUCT((SMIX2AT!$D$2:$D$200=$B10)*(SMIX2AT!$H$2:$H$200="P5")*SMIX2AT!$I$2:$I$200*0.01)))) -> 1 | N10: =IF($B10="",0,IFERROR(SUMPRODUCT((SMIX2AT!$D$2:$D$200=$B10)*SMIX2AT!$I$2:$I$200),0)) -> 0 | O10: =D10+F10+H10+J10+L10 -> 0
A11: Iván Gavilán Zafra | C11: igavilan@alumnat.copernic.cat | D11: =IF($B11="",0,COUNTIFS(SMIX2AT!$D$2:$D$200,$B11,SMIX2AT!$H$2:$H$200,"P1")) -> 0 | E11: =MAX(0.5,MIN(1.5,1+IF($B11="",0,SUMPRODUCT((SMIX2AT!$D$2:$D$200=$B11)*(SMIX2AT!$H$2:$H$200="P1")*SMIX2AT!$I$2:$I$200*0.01)))) -> 1 | F11: =IF($B11="",0,COUNTIFS(SMIX2AT!$D$2:$D$200,$B11,SMIX2AT!$H$2:$H$200,"P2")) -> 0 | G11: =MAX(0.5,MIN(1.5,1+IF($B11="",0,SUMPRODUCT((SMIX2AT!$D$2:$D$200=$B11)*(SMIX2AT!$H$2:$H$200="P2")*SMIX2AT!$I$2:$I$200*0.01)))) -> 1 | H11: =IF($B11="",0,COUNTIFS(SMIX2AT!$D$2:$D$200,$B11,SMIX2AT!$H$2:$H$200,"P3")) -> 0 | I11: =MAX(0.5,MIN(1.5,1+IF($B11="",0,SUMPRODUCT((SMIX2AT!$D$2:$D$200=$B11)*(SMIX2AT!$H$2:$H$200="P3")*SMIX2AT!$I$2:$I$200*0.01)))) -> 1 | J11: =IF($B11="",0,COUNTIFS(SMIX2AT!$D$2:$D$200,$B11,SMIX2AT!$H$2:$H$200,"P4")) -> 0 | K11: =MAX(0.5,MIN(1.5,1+IF($B11="",0,SUMPRODUCT((SMIX2AT!$D$2:$D$200=$B11)*(SMIX2AT!$H$2:$H$200="P4")*SMIX2AT!$I$2:$I$200*0.01)))) -> 1 | L11: =IF($B11="",0,COUNTIFS(SMIX2AT!$D$2:$D$200,$B11,SMIX2AT!$H$2:$H$200,"P5")) -> 0 | M11: =MAX(0.5,MIN(1.5,1+IF($B11="",0,SUMPRODUCT((SMIX2AT!$D$2:$D$200=$B11)*(SMIX2AT!$H$2:$H$200="P5")*SMIX2AT!$I$2:$I$200*0.01)))) -> 1 | N11: =IF($B11="",0,IFERROR(SUMPRODUCT((SMIX2AT!$D$2:$D$200=$B11)*SMIX2AT!$I$2:$I$200),0)) -> 0 | O11: =D11+F11+H11+J11+L11 -> 0
A12: Mohammed Taha Khadiri Alalech | C12: mtkhadiri@alumnat.copernic.cat | D12: =IF($B12="",0,COUNTIFS(SMIX2AT!$D$2:$D$200,$B12,SMIX2AT!$H$2:$H$200,"P1")) -> 0 | E12: =MAX(0.5,MIN(1.5,1+IF($B12="",0,SUMPRODUCT((SMIX2AT!$D$2:$D$200=$B12)*(SMIX2AT!$H$2:$H$200="P1")*SMIX2AT!$I$2:$I$200*0.01)))) -> 1 | F12: =IF($B12="",0,COUNTIFS(SMIX2AT!$D$2:$D$200,$B12,SMIX2AT!$H$2:$H$200,"P2")) -> 0 | G12: =MAX(0.5,MIN(1.5,1+IF($B12="",0,SUMPRODUCT((SMIX2AT!$D$2:$D$200=$B12)*(SMIX2AT!$H$2:$H$200="P2")*SMIX2AT!$I$2:$I$200*0.01)))) -> 1 | H12: =IF($B12="",0,COUNTIFS(SMIX2AT!$D$2:$D$200,$B12,SMIX2AT!$H$2:$H$200,"P3")) -> 0 | I12: =MAX(0.5,MIN(1.5,1+IF($B12="",0,SUMPRODUCT((SMIX2AT!$D$2:$D$200=$B12)*(SMIX2AT!$H$2:$H$200="P3")*SMIX2AT!$I$2:$I$200*0.01)))) -> 1 | J12: =IF($B12="",0,COUNTIFS(SMIX2AT!$D$2:$D$200,$B12,SMIX2AT!$H$2:$H$200,"P4")) -> 0 | K12: =MAX(0.5,MIN(1.5,1+IF($B12="",0,SUMPRODUCT((SMIX2AT!$D$2:$D$200=$B12)*(SMIX2AT!$H$2:$H$200="P4")*SMIX2AT!$I$2:$I$200*0.01)))) -> 1 | L12: =IF($B12="",0,COUNTIFS(SMIX2AT!$D$2:$D$200,$B12,SMIX2AT!$H$2:$H$200,"P5")) -> 0 | M12: =MAX(0.5,MIN(1.5,1+IF($B12="",0,SUMPRODUCT((SMIX2AT!$D$2:$D$200=$B12)*(SMIX2AT!$H$2:$H$200="P5")*SMIX2AT!$I$2:$I$200*0.01)))) -> 1 | N12: =IF($B12="",0,IFERROR(SUMPRODUCT((SMIX2AT!$D$2:$D$200=$B12)*SMIX2AT!$I$2:$I$200),0)) -> 0 | O12: =D12+F12+H12+J12+L12 -> 0
A13: Max Martos Gasulla | C13: martos.gasulla.max@alumnat.copernic.cat | D13: =IF($B13="",0,COUNTIFS(SMIX2AT!$D$2:$D$200,$B13,SMIX2AT!$H$2:$H$200,"P1")) -> 0 | E13: =MAX(0.5,MIN(1.5,1+IF($B13="",0,SUMPRODUCT((SMIX2AT!$D$2:$D$200=$B13)*(SMIX2AT!$H$2:$H$200="P1")*SMIX2AT!$I$2:$I$200*0.01)))) -> 1 | F13: =IF($B13="",0,COUNTIFS(SMIX2AT!$D$2:$D$200,$B13,SMIX2AT!$H$2:$H$200,"P2")) -> 0 | G13: =MAX(0.5,MIN(1.5,1+IF($B13="",0,SUMPRODUCT((SMIX2AT!$D$2:$D$200=$B13)*(SMIX2AT!$H$2:$H$200="P2")*SMIX2AT!$I$2:$I$200*0.01)))) -> 1 | H13: =IF($B13="",0,COUNTIFS(SMIX2AT!$D$2:$D$200,$B13,SMIX2AT!$H$2:$H$200,"P3")) -> 0 | I13: =MAX(0.5,MIN(1.5,1+IF($B13="",0,SUMPRODUCT((SMIX2AT!$D$2:$D$200=$B13)*(SMIX2AT!$H$2:$H$200="P3")*SMIX2AT!$I$2:$I$200*0.01)))) -> 1 | J13: =IF($B13="",0,COUNTIFS(SMIX2AT!$D$2:$D$200,$B13,SMIX2AT!$H$2:$H$200,"P4")) -> 0 | K13: =MAX(0.5,MIN(1.5,1+IF($B13="",0,SUMPRODUCT((SMIX2AT!$D$2:$D$200=$B13)*(SMIX2AT!$H$2:$H$200="P4")*SMIX2AT!$I$2:$I$200*0.01)))) -> 1 | L13: =IF($B13="",0,COUNTIFS(SMIX2AT!$D$2:$D$200,$B13,SMIX2AT!$H$2:$H$200,"P5")) -> 0 | M13: =MAX(0.5,MIN(1.5,1+IF($B13="",0,SUMPRODUCT((SMIX2AT!$D$2:$D$200=$B13)*(SMIX2AT!$H$2:$H$200="P5")*SMIX2AT!$I$2:$I$200*0.01)))) -> 1 | N13: =IF($B13="",0,IFERROR(SUMPRODUCT((SMIX2AT!$D$2:$D$200=$B13)*SMIX2AT!$I$2:$I$200),0)) -> 0 | O13: =D13+F13+H13+J13+L13 -> 0
A14: David Molina Sánchez | C14: molina.sanchez.david@alumnat.copernic.cat | D14: =IF($B14="",0,COUNTIFS(SMIX2AT!$D$2:$D$200,$B14,SMIX2AT!$H$2:$H$200,"P1")) -> 0 | E14: =MAX(0.5,MIN(1.5,1+IF($B14="",0,SUMPRODUCT((SMIX2AT!$D$2:$D$200=$B14)*(SMIX2AT!$H$2:$H$200="P1")*SMIX2AT!$I$2:$I$200*0.01)))) -> 1 | F14: =IF($B14="",0,COUNTIFS(SMIX2AT!$D$2:$D$200,$B14,SMIX2AT!$H$2:$H$200,"P2")) -> 0 | G14: =MAX(0.5,MIN(1.5,1+IF($B14="",0,SUMPRODUCT((SMIX2AT!$D$2:$D$200=$B14)*(SMIX2AT!$H$2:$H$200="P2")*SMIX2AT!$I$2:$I$200*0.01)))) -> 1 | H14: =IF($B14="",0,COUNTIFS(SMIX2AT!$D$2:$D$200,$B14,SMIX2AT!$H$2:$H$200,"P3")) -> 0 | I14: =MAX(0.5,MIN(1.5,1+IF($B14="",0,SUMPRODUCT((SMIX2AT!$D$2:$D$200=$B14)*(SMIX2AT!$H$2:$H$200="P3")*SMIX2AT!$I$2:$I$200*0.01)))) -> 1 | J14: =IF($B14="",0,COUNTIFS(SMIX2AT!$D$2:$D$200,$B14,SMIX2AT!$H$2:$H$200,"P4")) -> 0 | K14: =MAX(0.5,MIN(1.5,1+IF($B14="",0,SUMPRODUCT((SMIX2AT!$D$2:$D$200=$B14)*(SMIX2AT!$H$2:$H$200="P4")*SMIX2AT!$I$2:$I$200*0.01)))) -> 1 | L14: =IF($B14="",0,COUNTIFS(SMIX2AT!$D$2:$D$200,$B14,SMIX2AT!$H$2:$H$200,"P5")) -> 0 | M14: =MAX(0.5,MIN(1.5,1+IF($B14="",0,SUMPRODUCT((SMIX2AT!$D$2:$D$200=$B14)*(SMIX2AT!$H$2:$H$200="P5")*SMIX2AT!$I$2:$I$200*0.01)))) -> 1 | N14: =IF($B14="",0,IFERROR(SUMPRODUCT((SMIX2AT!$D$2:$D$200=$B14)*SMIX2AT!$I$2:$I$200),0)) -> 0 | O14: =D14+F14+H14+J14+L14 -> 0
... A22: Marc Zaragoza López | C22: mzaragoza@alumnat.copernic.cat | D22: =IF($B22="",0,COUNTIFS(SMIX2AT!$D$2:$D$200,$B22,SMIX2AT!$H$2:$H$200,"P1")) -> 0 | E22: =MAX(0.5,MIN(1.5,1+IF($B22="",0,SUMPRODUCT((SMIX2AT!$D$2:$D$200=$B22)*(SMIX2AT!$H$2:$H$200="P1")*SMIX2AT!$I$2:$I$200*0.01)))) -> 1 | F22: =IF($B22="",0,COUNTIFS(SMIX2AT!$D$2:$D$200,$B22,SMIX2AT!$H$2:$H$200,"P2")) -> 0 | G22: =MAX(0.5,MIN(1.5,1+IF($B22="",0,SUMPRODUCT((SMIX2AT!$D$2:$D$200=$B22)*(SMIX2AT!$H$2:$H$200="P2")*SMIX2AT!$I$2:$I$200*0.01)))) -> 1 | H22: =IF($B22="",0,COUNTIFS(SMIX2AT!$D$2:$D$200,$B22,SMIX2AT!$H$2:$H$200,"P3")) -> 0 | I22: =MAX(0.5,MIN(1.5,1+IF($B22="",0,SUMPRODUCT((SMIX2AT!$D$2:$D$200=$B22)*(SMIX2AT!$H$2:$H$200="P3")*SMIX2AT!$I$2:$I$200*0.01)))) -> 1 | J22: =IF($B22="",0,COUNTIFS(SMIX2AT!$D$2:$D$200,$B22,SMIX2AT!$H$2:$H$200,"P4")) -> 0 | K22: =MAX(0.5,MIN(1.5,1+IF($B22="",0,SUMPRODUCT((SMIX2AT!$D$2:$D$200=$B22)*(SMIX2AT!$H$2:$H$200="P4")*SMIX2AT!$I$2:$I$200*0.01)))) -> 1 | L22: =IF($B22="",0,COUNTIFS(SMIX2AT!$D$2:$D$200,$B22,SMIX2AT!$H$2:$H$200,"P5")) -> 0 | M22: =MAX(0.5,MIN(1.5,1+IF($B22="",0,SUMPRODUCT((SMIX2AT!$D$2:$D$200=$B22)*(SMIX2AT!$H$2:$H$200="P5")*SMIX2AT!$I$2:$I$200*0.01)))) -> 1 | N22: =IF($B22="",0,IFERROR(SUMPRODUCT((SMIX2AT!$D$2:$D$200=$B22)*SMIX2AT!$I$2:$I$200),0)) -> 0 | O22: =D22+F22+H22+J22+L22 -> 0
D23: =IF($B23="",0,COUNTIFS(SMIX2AT!$D$2:$D$200,$B23,SMIX2AT!$H$2:$H$200,"P1")) -> 0 | E23: =MAX(0.5,MIN(1.5,1+IF($B23="",0,SUMPRODUCT((SMIX2AT!$D$2:$D$200=$B23)*(SMIX2AT!$H$2:$H$200="P1")*SMIX2AT!$I$2:$I$200*0.01)))) -> 1 | F23: =IF($B23="",0,COUNTIFS(SMIX2AT!$D$2:$D$200,$B23,SMIX2AT!$H$2:$H$200,"P2")) -> 0 | G23: =MAX(0.5,MIN(1.5,1+IF($B23="",0,SUMPRODUCT((SMIX2AT!$D$2:$D$200=$B23)*(SMIX2AT!$H$2:$H$200="P2")*SMIX2AT!$I$2:$I$200*0.01)))) -> 1 | H23: =IF($B23="",0,COUNTIFS(SMIX2AT!$D$2:$D$200,$B23,SMIX2AT!$H$2:$H$200,"P3")) -> 0 | I23: =MAX(0.5,MIN(1.5,1+IF($B23="",0,SUMPRODUCT((SMIX2AT!$D$2:$D$200=$B23)*(SMIX2AT!$H$2:$H$200="P3")*SMIX2AT!$I$2:$I$200*0.01)))) -> 1 | J23: =IF($B23="",0,COUNTIFS(SMIX2AT!$D$2:$D$200,$B23,SMIX2AT!$H$2:$H$200,"P4")) -> 0 | K23: =MAX(0.5,MIN(1.5,1+IF($B23="",0,SUMPRODUCT((SMIX2AT!$D$2:$D$200=$B23)*(SMIX2AT!$H$2:$H$200="P4")*SMIX2AT!$I$2:$I$200*0.01)))) -> 1 | L23: =IF($B23="",0,COUNTIFS(SMIX2AT!$D$2:$D$200,$B23,SMIX2AT!$H$2:$H$200,"P5")) -> 0 | M23: =MAX(0.5,MIN(1.5,1+IF($B23="",0,SUMPRODUCT((SMIX2AT!$D$2:$D$200=$B23)*(SMIX2AT!$H$2:$H$200="P5")*SMIX2AT!$I$2:$I$200*0.01)))) -> 1 | N23: =IF($B23="",0,IFERROR(SUMPRODUCT((SMIX2AT!$D$2:$D$200=$B23)*SMIX2AT!$I$2:$I$200),0)) -> 0 | O23: =D23+F23+H23+J23+L23 -> 0
D24: =IF($B24="",0,COUNTIFS(SMIX2AT!$D$2:$D$200,$B24,SMIX2AT!$H$2:$H$200,"P1")) -> 0 | E24: =MAX(0.5,MIN(1.5,1+IF($B24="",0,SUMPRODUCT((SMIX2AT!$D$2:$D$200=$B24)*(SMIX2AT!$H$2:$H$200="P1")*SMIX2AT!$I$2:$I$200*0.01)))) -> 1 | F24: =IF($B24="",0,COUNTIFS(SMIX2AT!$D$2:$D$200,$B24,SMIX2AT!$H$2:$H$200,"P2")) -> 0 | G24: =MAX(0.5,MIN(1.5,1+IF($B24="",0,SUMPRODUCT((SMIX2AT!$D$2:$D$200=$B24)*(SMIX2AT!$H$2:$H$200="P2")*SMIX2AT!$I$2:$I$200*0.01)))) -> 1 | H24: =IF($B24="",0,COUNTIFS(SMIX2AT!$D$2:$D$200,$B24,SMIX2AT!$H$2:$H$200,"P3")) -> 0 | I24: =MAX(0.5,MIN(1.5,1+IF($B24="",0,SUMPRODUCT((SMIX2AT!$D$2:$D$200=$B24)*(SMIX2AT!$H$2:$H$200="P3")*SMIX2AT!$I$2:$I$200*0.01)))) -> 1 | J24: =IF($B24="",0,COUNTIFS(SMIX2AT!$D$2:$D$200,$B24,SMIX2AT!$H$2:$H$200,"P4")) -> 0 | K24: =MAX(0.5,MIN(1.5,1+IF($B24="",0,SUMPRODUCT((SMIX2AT!$D$2:$D$200=$B24)*(SMIX2AT!$H$2:$H$200="P4")*SMIX2AT!$I$2:$I$200*0.01)))) -> 1 | L24: =IF($B24="",0,COUNTIFS(SMIX2AT!$D$2:$D$200,$B24,SMIX2AT!$H$2:$H$200,"P5")) -> 0 | M24: =MAX(0.5,MIN(1.5,1+IF($B24="",0,SUMPRODUCT((SMIX2AT!$D$2:$D$200=$B24)*(SMIX2AT!$H$2:$H$200="P5")*SMIX2AT!$I$2:$I$200*0.01)))) -> 1 | N24: =IF($B24="",0,IFERROR(SUMPRODUCT((SMIX2AT!$D$2:$D$200=$B24)*SMIX2AT!$I$2:$I$200),0)) -> 0 | O24: =D24+F24+H24+J24+L24 -> 0
D25: =IF($B25="",0,COUNTIFS(SMIX2AT!$D$2:$D$200,$B25,SMIX2AT!$H$2:$H$200,"P1")) -> 0 | E25: =MAX(0.5,MIN(1.5,1+IF($B25="",0,SUMPRODUCT((SMIX2AT!$D$2:$D$200=$B25)*(SMIX2AT!$H$2:$H$200="P1")*SMIX2AT!$I$2:$I$200*0.01)))) -> 1 | F25: =IF($B25="",0,COUNTIFS(SMIX2AT!$D$2:$D$200,$B25,SMIX2AT!$H$2:$H$200,"P2")) -> 0 | G25: =MAX(0.5,MIN(1.5,1+IF($B25="",0,SUMPRODUCT((SMIX2AT!$D$2:$D$200=$B25)*(SMIX2AT!$H$2:$H$200="P2")*SMIX2AT!$I$2:$I$200*0.01)))) -> 1 | H25: =IF($B25="",0,COUNTIFS(SMIX2AT!$D$2:$D$200,$B25,SMIX2AT!$H$2:$H$200,"P3")) -> 0 | I25: =MAX(0.5,MIN(1.5,1+IF($B25="",0,SUMPRODUCT((SMIX2AT!$D$2:$D$200=$B25)*(SMIX2AT!$H$2:$H$200="P3")*SMIX2AT!$I$2:$I$200*0.01)))) -> 1 | J25: =IF($B25="",0,COUNTIFS(SMIX2AT!$D$2:$D$200,$B25,SMIX2AT!$H$2:$H$200,"P4")) -> 0 | K25: =MAX(0.5,MIN(1.5,1+IF($B25="",0,SUMPRODUCT((SMIX2AT!$D$2:$D$200=$B25)*(SMIX2AT!$H$2:$H$200="P4")*SMIX2AT!$I$2:$I$200*0.01)))) -> 1 | L25: =IF($B25="",0,COUNTIFS(SMIX2AT!$D$2:$D$200,$B25,SMIX2AT!$H$2:$H$200,"P5")) -> 0 | M25: =MAX(0.5,MIN(1.5,1+IF($B25="",0,SUMPRODUCT((SMIX2AT!$D$2:$D$200=$B25)*(SMIX2AT!$H$2:$H$200="P5")*SMIX2AT!$I$2:$I$200*0.01)))) -> 1 | N25: =IF($B25="",0,IFERROR(SUMPRODUCT((SMIX2AT!$D$2:$D$200=$B25)*SMIX2AT!$I$2:$I$200),0)) -> 0 | O25: =D25+F25+H25+J25+L25 -> 0
D26: =IF($B26="",0,COUNTIFS(SMIX2AT!$D$2:$D$200,$B26,SMIX2AT!$H$2:$H$200,"P1")) -> 0 | E26: =MAX(0.5,MIN(1.5,1+IF($B26="",0,SUMPRODUCT((SMIX2AT!$D$2:$D$200=$B26)*(SMIX2AT!$H$2:$H$200="P1")*SMIX2AT!$I$2:$I$200*0.01)))) -> 1 | F26: =IF($B26="",0,COUNTIFS(SMIX2AT!$D$2:$D$200,$B26,SMIX2AT!$H$2:$H$200,"P2")) -> 0 | G26: =MAX(0.5,MIN(1.5,1+IF($B26="",0,SUMPRODUCT((SMIX2AT!$D$2:$D$200=$B26)*(SMIX2AT!$H$2:$H$200="P2")*SMIX2AT!$I$2:$I$200*0.01)))) -> 1 | H26: =IF($B26="",0,COUNTIFS(SMIX2AT!$D$2:$D$200,$B26,SMIX2AT!$H$2:$H$200,"P3")) -> 0 | I26: =MAX(0.5,MIN(1.5,1+IF($B26="",0,SUMPRODUCT((SMIX2AT!$D$2:$D$200=$B26)*(SMIX2AT!$H$2:$H$200="P3")*SMIX2AT!$I$2:$I$200*0.01)))) -> 1 | J26: =IF($B26="",0,COUNTIFS(SMIX2AT!$D$2:$D$200,$B26,SMIX2AT!$H$2:$H$200,"P4")) -> 0 | K26: =MAX(0.5,MIN(1.5,1+IF($B26="",0,SUMPRODUCT((SMIX2AT!$D$2:$D$200=$B26)*(SMIX2AT!$H$2:$H$200="P4")*SMIX2AT!$I$2:$I$200*0.01)))) -> 1 | L26: =IF($B26="",0,COUNTIFS(SMIX2AT!$D$2:$D$200,$B26,SMIX2AT!$H$2:$H$200,"P5")) -> 0 | M26: =MAX(0.5,MIN(1.5,1+IF($B26="",0,SUMPRODUCT((SMIX2AT!$D$2:$D$200=$B26)*(SMIX2AT!$H$2:$H$200="P5")*SMIX2AT!$I$2:$I$200*0.01)))) -> 1 | N26: =IF($B26="",0,IFERROR(SUMPRODUCT((SMIX2AT!$D$2:$D$200=$B26)*SMIX2AT!$I$2:$I$200),0)) -> 0 | O26: =D26+F26+H26+J26+L26 -> 0
D27: =IF($B27="",0,COUNTIFS(SMIX2AT!$D$2:$D$200,$B27,SMIX2AT!$H$2:$H$200,"P1")) -> 0 | E27: =MAX(0.5,MIN(1.5,1+IF($B27="",0,SUMPRODUCT((SMIX2AT!$D$2:$D$200=$B27)*(SMIX2AT!$H$2:$H$200="P1")*SMIX2AT!$I$2:$I$200*0.01)))) -> 1 | F27: =IF($B27="",0,COUNTIFS(SMIX2AT!$D$2:$D$200,$B27,SMIX2AT!$H$2:$H$200,"P2")) -> 0 | G27: =MAX(0.5,MIN(1.5,1+IF($B27="",0,SUMPRODUCT((SMIX2AT!$D$2:$D$200=$B27)*(SMIX2AT!$H$2:$H$200="P2")*SMIX2AT!$I$2:$I$200*0.01)))) -> 1 | H27: =IF($B27="",0,COUNTIFS(SMIX2AT!$D$2:$D$200,$B27,SMIX2AT!$H$2:$H$200,"P3")) -> 0 | I27: =MAX(0.5,MIN(1.5,1+IF($B27="",0,SUMPRODUCT((SMIX2AT!$D$2:$D$200=$B27)*(SMIX2AT!$H$2:$H$200="P3")*SMIX2AT!$I$2:$I$200*0.01)))) -> 1 | J27: =IF($B27="",0,COUNTIFS(SMIX2AT!$D$2:$D$200,$B27,SMIX2AT!$H$2:$H$200,"P4")) -> 0 | K27: =MAX(0.5,MIN(1.5,1+IF($B27="",0,SUMPRODUCT((SMIX2AT!$D$2:$D$200=$B27)*(SMIX2AT!$H$2:$H$200="P4")*SMIX2AT!$I$2:$I$200*0.01)))) -> 1 | L27: =IF($B27="",0,COUNTIFS(SMIX2AT!$D$2:$D$200,$B27,SMIX2AT!$H$2:$H$200,"P5")) -> 0 | M27: =MAX(0.5,MIN(1.5,1+IF($B27="",0,SUMPRODUCT((SMIX2AT!$D$2:$D$200=$B27)*(SMIX2AT!$H$2:$H$200="P5")*SMIX2AT!$I$2:$I$200*0.01)))) -> 1 | N27: =IF($B27="",0,IFERROR(SUMPRODUCT((SMIX2AT!$D$2:$D$200=$B27)*SMIX2AT!$I$2:$I$200),0)) -> 0 | O27: =D27+F27+H27+J27+L27 -> 0
D28: =IF($B28="",0,COUNTIFS(SMIX2AT!$D$2:$D$200,$B28,SMIX2AT!$H$2:$H$200,"P1")) -> 0 | E28: =MAX(0.5,MIN(1.5,1+IF($B28="",0,SUMPRODUCT((SMIX2AT!$D$2:$D$200=$B28)*(SMIX2AT!$H$2:$H$200="P1")*SMIX2AT!$I$2:$I$200*0.01)))) -> 1 | F28: =IF($B28="",0,COUNTIFS(SMIX2AT!$D$2:$D$200,$B28,SMIX2AT!$H$2:$H$200,"P2")) -> 0 | G28: =MAX(0.5,MIN(1.5,1+IF($B28="",0,SUMPRODUCT((SMIX2AT!$D$2:$D$200=$B28)*(SMIX2AT!$H$2:$H$200="P2")*SMIX2AT!$I$2:$I$200*0.01)))) -> 1 | H28: =IF($B28="",0,COUNTIFS(SMIX2AT!$D$2:$D$200,$B28,SMIX2AT!$H$2:$H$200,"P3")) -> 0 | I28: =MAX(0.5,MIN(1.5,1+IF($B28="",0,SUMPRODUCT((SMIX2AT!$D$2:$D$200=$B28)*(SMIX2AT!$H$2:$H$200="P3")*SMIX2AT!$I$2:$I$200*0.01)))) -> 1 | J28: =IF($B28="",0,COUNTIFS(SMIX2AT!$D$2:$D$200,$B28,SMIX2AT!$H$2:$H$200,"P4")) -> 0 | K28: =MAX(0.5,MIN(1.5,1+IF($B28="",0,SUMPRODUCT((SMIX2AT!$D$2:$D$200=$B28)*(SMIX2AT!$H$2:$H$200="P4")*SMIX2AT!$I$2:$I$200*0.01)))) -> 1 | L28: =IF($B28="",0,COUNTIFS(SMIX2AT!$D$2:$D$200,$B28,SMIX2AT!$H$2:$H$200,"P5")) -> 0 | M28: =MAX(0.5,MIN(1.5,1+IF($B28="",0,SUMPRODUCT((SMIX2AT!$D$2:$D$200=$B28)*(SMIX2AT!$H$2:$H$200="P5")*SMIX2AT!$I$2:$I$200*0.01)))) -> 1 | N28: =IF($B28="",0,IFERROR(SUMPRODUCT((SMIX2AT!$D$2:$D$200=$B28)*SMIX2AT!$I$2:$I$200),0)) -> 0 | O28: =D28+F28+H28+J28+L28 -> 0
D29: =IF($B29="",0,COUNTIFS(SMIX2AT!$D$2:$D$200,$B29,SMIX2AT!$H$2:$H$200,"P1")) -> 0 | E29: =MAX(0.5,MIN(1.5,1+IF($B29="",0,SUMPRODUCT((SMIX2AT!$D$2:$D$200=$B29)*(SMIX2AT!$H$2:$H$200="P1")*SMIX2AT!$I$2:$I$200*0.01)))) -> 1 | F29: =IF($B29="",0,COUNTIFS(SMIX2AT!$D$2:$D$200,$B29,SMIX2AT!$H$2:$H$200,"P2")) -> 0 | G29: =MAX(0.5,MIN(1.5,1+IF($B29="",0,SUMPRODUCT((SMIX2AT!$D$2:$D$200=$B29)*(SMIX2AT!$H$2:$H$200="P2")*SMIX2AT!$I$2:$I$200*0.01)))) -> 1 | H29: =IF($B29="",0,COUNTIFS(SMIX2AT!$D$2:$D$200,$B29,SMIX2AT!$H$2:$H$200,"P3")) -> 0 | I29: =MAX(0.5,MIN(1.5,1+IF($B29="",0,SUMPRODUCT((SMIX2AT!$D$2:$D$200=$B29)*(SMIX2AT!$H$2:$H$200="P3")*SMIX2AT!$I$2:$I$200*0.01)))) -> 1 | J29: =IF($B29="",0,COUNTIFS(SMIX2AT!$D$2:$D$200,$B29,SMIX2AT!$H$2:$H$200,"P4")) -> 0 | K29: =MAX(0.5,MIN(1.5,1+IF($B29="",0,SUMPRODUCT((SMIX2AT!$D$2:$D$200=$B29)*(SMIX2AT!$H$2:$H$200="P4")*SMIX2AT!$I$2:$I$200*0.01)))) -> 1 | L29: =IF($B29="",0,COUNTIFS(SMIX2AT!$D$2:$D$200,$B29,SMIX2AT!$H$2:$H$200,"P5")) -> 0 | M29: =MAX(0.5,MIN(1.5,1+IF($B29="",0,SUMPRODUCT((SMIX2AT!$D$2:$D$200=$B29)*(SMIX2AT!$H$2:$H$200="P5")*SMIX2AT!$I$2:$I$200*0.01)))) -> 1 | N29: =IF($B29="",0,IFERROR(SUMPRODUCT((SMIX2AT!$D$2:$D$200=$B29)*SMIX2AT!$I$2:$I$200),0)) -> 0 | O29: =D29+F29+H29+J29+L29 -> 0
D30: =IF($B30="",0,COUNTIFS(SMIX2AT!$D$2:$D$200,$B30,SMIX2AT!$H$2:$H$200,"P1")) -> 0 | E30: =MAX(0.5,MIN(1.5,1+IF($B30="",0,SUMPRODUCT((SMIX2AT!$D$2:$D$200=$B30)*(SMIX2AT!$H$2:$H$200="P1")*SMIX2AT!$I$2:$I$200*0.01)))) -> 1 | F30: =IF($B30="",0,COUNTIFS(SMIX2AT!$D$2:$D$200,$B30,SMIX2AT!$H$2:$H$200,"P2")) -> 0 | G30: =MAX(0.5,MIN(1.5,1+IF($B30="",0,SUMPRODUCT((SMIX2AT!$D$2:$D$200=$B30)*(SMIX2AT!$H$2:$H$200="P2")*SMIX2AT!$I$2:$I$200*0.01)))) -> 1 | H30: =IF($B30="",0,COUNTIFS(SMIX2AT!$D$2:$D$200,$B30,SMIX2AT!$H$2:$H$200,"P3")) -> 0 | I30: =MAX(0.5,MIN(1.5,1+IF($B30="",0,SUMPRODUCT((SMIX2AT!$D$2:$D$200=$B30)*(SMIX2AT!$H$2:$H$200="P3")*SMIX2AT!$I$2:$I$200*0.01)))) -> 1 | J30: =IF($B30="",0,COUNTIFS(SMIX2AT!$D$2:$D$200,$B30,SMIX2AT!$H$2:$H$200,"P4")) -> 0 | K30: =MAX(0.5,MIN(1.5,1+IF($B30="",0,SUMPRODUCT((SMIX2AT!$D$2:$D$200=$B30)*(SMIX2AT!$H$2:$H$200="P4")*SMIX2AT!$I$2:$I$200*0.01)))) -> 1 | L30: =IF($B30="",0,COUNTIFS(SMIX2AT!$D$2:$D$200,$B30,SMIX2AT!$H$2:$H$200,"P5")) -> 0 | M30: =MAX(0.5,MIN(1.5,1+IF($B30="",0,SUMPRODUCT((SMIX2AT!$D$2:$D$200=$B30)*(SMIX2AT!$H$2:$H$200="P5")*SMIX2AT!$I$2:$I$200*0.01)))) -> 1 | N30: =IF($B30="",0,IFERROR(SUMPRODUCT((SMIX2AT!$D$2:$D$200=$B30)*SMIX2AT!$I$2:$I$200),0)) -> 0 | O30: =D30+F30+H30+J30+L30 -> 0
A31: Recull incidències per alumne | C31: Selector alumne | D31: =IF($B31="",0,COUNTIFS(SMIX2AT!$D$2:$D$200,$B31,SMIX2AT!$H$2:$H$200,"P1")) -> 0 | E31: =MAX(0.5,MIN(1.5,1+IF($B31="",0,SUMPRODUCT((SMIX2AT!$D$2:$D$200=$B31)*(SMIX2AT!$H$2:$H$200="P1")*SMIX2AT!$I$2:$I$200*0.01)))) -> 1 | F31: =IF($B31="",0,COUNTIFS(SMIX2AT!$D$2:$D$200,$B31,SMIX2AT!$H$2:$H$200,"P2")) -> 0 | G31: =MAX(0.5,MIN(1.5,1+IF($B31="",0,SUMPRODUCT((SMIX2AT!$D$2:$D$200=$B31)*(SMIX2AT!$H$2:$H$200="P2")*SMIX2AT!$I$2:$I$200*0.01)))) -> 1 | H31: =IF($B31="",0,COUNTIFS(SMIX2AT!$D$2:$D$200,$B31,SMIX2AT!$H$2:$H$200,"P3")) -> 0 | I31: =MAX(0.5,MIN(1.5,1+IF($B31="",0,SUMPRODUCT((SMIX2AT!$D$2:$D$200=$B31)*(SMIX2AT!$H$2:$H$200="P3")*SMIX2AT!$I$2:$I$200*0.01)))) -> 1 | J31: =IF($B31="",0,COUNTIFS(SMIX2AT!$D$2:$D$200,$B31,SMIX2AT!$H$2:$H$200,"P4")) -> 0 | K31: =MAX(0.5,MIN(1.5,1+IF($B31="",0,SUMPRODUCT((SMIX2AT!$D$2:$D$200=$B31)*(SMIX2AT!$H$2:$H$200="P4")*SMIX2AT!$I$2:$I$200*0.01)))) -> 1 | L31: =IF($B31="",0,COUNTIFS(SMIX2AT!$D$2:$D$200,$B31,SMIX2AT!$H$2:$H$200,"P5")) -> 0 | M31: =MAX(0.5,MIN(1.5,1+IF($B31="",0,SUMPRODUCT((SMIX2AT!$D$2:$D$200=$B31)*(SMIX2AT!$H$2:$H$200="P5")*SMIX2AT!$I$2:$I$200*0.01)))) -> 1 | N31: =IF($B31="",0,IFERROR(SUMPRODUCT((SMIX2AT!$D$2:$D$200=$B31)*SMIX2AT!$I$2:$I$200),0)) -> 0 | O31: =D31+F31+H31+J31+L31 -> 0
A32: Query que llista les observacions de millors a pitjors durant el període de treball | D32: =IF($B32="",0,COUNTIFS(SMIX2AT!$D$2:$D$200,$B32,SMIX2AT!$H$2:$H$200,"P1")) -> 0 | E32: =MAX(0.5,MIN(1.5,1+IF($B32="",0,SUMPRODUCT((SMIX2AT!$D$2:$D$200=$B32)*(SMIX2AT!$H$2:$H$200="P1")*SMIX2AT!$I$2:$I$200*0.01)))) -> 1 | F32: =IF($B32="",0,COUNTIFS(SMIX2AT!$D$2:$D$200,$B32,SMIX2AT!$H$2:$H$200,"P2")) -> 0 | G32: =MAX(0.5,MIN(1.5,1+IF($B32="",0,SUMPRODUCT((SMIX2AT!$D$2:$D$200=$B32)*(SMIX2AT!$H$2:$H$200="P2")*SMIX2AT!$I$2:$I$200*0.01)))) -> 1 | H32: =IF($B32="",0,COUNTIFS(SMIX2AT!$D$2:$D$200,$B32,SMIX2AT!$H$2:$H$200,"P3")) -> 0 | I32: =MAX(0.5,MIN(1.5,1+IF($B32="",0,SUMPRODUCT((SMIX2AT!$D$2:$D$200=$B32)*(SMIX2AT!$H$2:$H$200="P3")*SMIX2AT!$I$2:$I$200*0.01)))) -> 1 | J32: =IF($B32="",0,COUNTIFS(SMIX2AT!$D$2:$D$200,$B32,SMIX2AT!$H$2:$H$200,"P4")) -> 0 | K32: =MAX(0.5,MIN(1.5,1+IF($B32="",0,SUMPRODUCT((SMIX2AT!$D$2:$D$200=$B32)*(SMIX2AT!$H$2:$H$200="P4")*SMIX2AT!$I$2:$I$200*0.01)))) -> 1 | L32: =IF($B32="",0,COUNTIFS(SMIX2AT!$D$2:$D$200,$B32,SMIX2AT!$H$2:$H$200,"P5")) -> 0 | M32: =MAX(0.5,MIN(1.5,1+IF($B32="",0,SUMPRODUCT((SMIX2AT!$D$2:$D$200=$B32)*(SMIX2AT!$H$2:$H$200="P5")*SMIX2AT!$I$2:$I$200*0.01)))) -> 1 | N32: =IF($B32="",0,IFERROR(SUMPRODUCT((SMIX2AT!$D$2:$D$200=$B32)*SMIX2AT!$I$2:$I$200),0)) -> 0 | O32: =D32+F32+H32+J32+L32 -> 0

Sheet SMIX2BT
A1: Marca de temps | B1: Adreça electrònica | C1: Professor | D1: Alumne | E1: Competència transversal observada | F1: Valoració | G1: Descripció breu del comportament observat | H1: Quin projecte estem fent? | I1: Puntuació
I2: =IF(F2="",0,IFERROR(VALUE(LEFT(TRIM(F2),FIND(" ",TRIM(F2))-1)),0)) -> 0
I3: =IF(F3="",0,IFERROR(VALUE(LEFT(TRIM(F3),FIND(" ",TRIM(F3))-1)),0)) -> 0
I4: =IF(F4="",0,IFERROR(VALUE(LEFT(TRIM(F4),FIND(" ",TRIM(F4))-1)),0)) -> 0
I5: =IF(F5="",0,IFERROR(VALUE(LEFT(TRIM(F5),FIND(" ",TRIM(F5))-1)),0)) -> 0
I6: =IF(F6="",0,IFERROR(VALUE(LEFT(TRIM(F6),FIND(" ",TRIM(F6))-1)),0)) -> 0
I7: =IF(F7="",0,IFERROR(VALUE(LEFT(TRIM(F7),FIND(" ",TRIM(F7))-1)),0)) -> 0
I8: =IF(F8="",0,IFERROR(VALUE(LEFT(TRIM(F8),FIND(" ",TRIM(F8))-1)),0)) -> 0
I9: =IF(F9="",0,IFERROR(VALUE(LEFT(TRIM(F9),FIND(" ",TRIM(F9))-1)),0)) -> 0
I10: =IF(F10="",0,IFERROR(VALUE(LEFT(TRIM(F10),FIND(" ",TRIM(F10))-1)),0)) -> 0
I11: =IF(F11="",0,IFERROR(VALUE(LEFT(TRIM(F11),FIND(" ",TRIM(F11))-1)),0)) -> 0
I12: =IF(F12="",0,IFERROR(VALUE(LEFT(TRIM(F12),FIND(" ",TRIM(F12))-1)),0)) -> 0
I13: =IF(F13="",0,IFERROR(VALUE(LEFT(TRIM(F13),FIND(" ",TRIM(F13))-1)),0)) -> 0
... I200: =IF(F200="",0,IFERROR(VALUE(LEFT(TRIM(F200),FIND(" ",TRIM(F200))-1)),0)) -> 0

Sheet Alumnes_B
A1: SMIX2CT
A2: Nom i cognoms | B2: Cognoms, nom | C2: correu | D2: P1-obs | E2: P1-balanç | F2: P2-obs | G2: P2-balanç | H2: P3-obs | I2: P3-balanç | J2: P4-obs | K2: P4-balanç | L2: P5-obs | M2: P5-balanç | N2: Puntuació neta | O2: Total observacions
A3: Rodrigo Jesus Corredor Garcia | C3: rjcorredor@alumnat.copernic.cat | D3: =IF($B3="",0,COUNTIFS(SMIX2BT!$D$2:$D$200,$B3,SMIX2BT!$H$2:$H$200,"P1")) -> 0 | E3: =MAX(0.5,MIN(1.5,1+IF($B3="",0,SUMPRODUCT((SMIX2BT!$D$2:$D$200=$B3)*(SMIX2BT!$H$2:$H$200="P1")*SMIX2BT!$I$2:$I$200*0.01)))) -> 1 | F3: =IF($B3="",0,COUNTIFS(SMIX2BT!$D$2:$D$200,$B3,SMIX2BT!$H$2:$H$200,"P2")) -> 0 | G3: =MAX(0.5,MIN(1.5,1+IF($B3="",0,SUMPRODUCT((SMIX2BT!$D$2:$D$200=$B3)*(SMIX2BT!$H$2:$H$200="P2")*SMIX2BT!$I$2:$I$200*0.01)))) -> 1 | H3: =IF($B3="",0,COUNTIFS(SMIX2BT!$D$2:$D$200,$B3,SMIX2BT!$H$2:$H$200,"P3")) -> 0 | I3: =MAX(0.5,MIN(1.5,1+IF($B3="",0,SUMPRODUCT((SMIX2BT!$D$2:$D$200=$B3)*(SMIX2BT!$H$2:$H$200="P3")*SMIX2BT!$I$2:$I$200*0.01)))) -> 1 | J3: =IF($B3="",0,COUNTIFS(SMIX2BT!$D$2:$D$200,$B3,SMIX2BT!$H$2:$H$200,"P4")) -> 0 | K3: =MAX(0.5,MIN(1.5,1+IF($B3="",0,SUMPRODUCT((SMIX2BT!$D$2:$D$200=$B3)*(SMIX2BT!$H$2:$H$200="P4")*SMIX2BT!$I$2:$I$200*0.01)))) -> 1 | L3: =IF($B3="",0,COUNTIFS(SMIX2BT!$D$2:$D$200,$B3,SMIX2BT!$H$2:$H$200,"P5")) -> 0 | M3: =MAX(0.5,MIN(1.5,1+IF($B3="",0,SUMPRODUCT((SMIX2BT!$D$2:$D$200=$B3)*(SMIX2BT!$H$2:$H$200="P5")*SMIX2BT!$I$2:$I$200*0.01)))) -> 1 | N3: =IF($B3="",0,IFERROR(SUMPRODUCT((SMIX2BT!$D$2:$D$200=$B3)*SMIX2BT!$I$2:$I$200),0)) -> 0 | O3: =D3+F3+H3+J3+L3 -> 0
A4: Oussama El Idrissi | C4: oelidrissi@alumnat.copernic.cat | D4: =IF($B4="",0,COUNTIFS(SMIX2BT!$D$2:$D$200,$B4,SMIX2BT!$H$2:$H$200,"P1")) -> 0 | E4: =MAX(0.5,MIN(1.5,1+IF($B4="",0,SUMPRODUCT((SMIX2BT!$D$2:$D$200=$B4)*(SMIX2BT!$H$2:$H$200="P1")*SMIX2BT!$I$2:$I$200*0.01)))) -> 1 | F4: =IF($B4="",0,COUNTIFS(SMIX2BT!$D$2:$D$200,$B4,SMIX2BT!$H$2:$H$200,"P2")) -> 0 | G4: =MAX(0.5,MIN(1.5,1+IF($B4="",0,SUMPRODUCT((SMIX2BT!$D$2:$D$200=$B4)*(SMIX2BT!$H$2:$H$200="P2")*SMIX2BT!$I$2:$I$200*0.01)))) -> 1 | H4: =IF($B4="",0,COUNTIFS(SMIX2BT!$D$2:$D$200,$B4,SMIX2BT!$H$2:$H$200,"P3")) -> 0 | I4: =MAX(0.5,MIN(1.5,1+IF($B4="",0,SUMPRODUCT((SMIX2BT!$D$2:$D$200=$B4)*(SMIX2BT!$H$2:$H$200="P3")*SMIX2BT!$I$2:$I$200*0.01)))) -> 1 | J4: =IF($B4="",0,COUNTIFS(SMIX2BT!$D$2:$D$200,$B4,SMIX2BT!$H$2:$H$200,"P4")) -> 0 | K4: =MAX(0.5,MIN(1.5,1+IF($B4="",0,SUMPRODUCT((SMIX2BT!$D$2:$D$200=$B4)*(SMIX2BT!$H$2:$H$200="P4")*SMIX2BT!$I$2:$I$200*0.01)))) -> 1 | L4: =IF($B4="",0,COUNTIFS(SMIX2BT!$D$2:$D$200,$B4,SMIX2BT!$H$2:$H$200,"P5")) -> 0 | M4: =MAX(0.5,MIN(1.5,1+IF($B4="",0,SUMPRODUCT((SMIX2BT!$D$2:$D$200=$B4)*(SMIX2BT!$H$2:$H$200="P5")*SMIX2BT!$I$2:$I$200*0.01)))) -> 1 | N4: =IF($B4="",0,IFERROR(SUMPRODUCT((SMIX2BT!$D$2:$D$200=$B4)*SMIX2BT!$I$2:$I$200),0)) -> 0 | O4: =D4+F4+H4+J4+L4 -> 0
A5: Aitor Fenoy Fernández | C5: afenoy@alumnat.copernic.cat | D5: =IF($B5="",0,COUNTIFS(SMIX2BT!$D$2:$D$200,$B5,SMIX2BT!$H$2:$H$200,"P1")) -> 0 | E5: =MAX(0.5,MIN(1.5,1+IF($B5="",0,SUMPRODUCT((SMIX2BT!$D$2:$D$200=$B5)*(SMIX2BT!$H$2:$H$200="P1")*SMIX2BT!$I$2:$I$200*0.01)))) -> 1 | F5: =IF($B5="",0,COUNTIFS(SMIX2BT!$D$2:$D$200,$B5,SMIX2BT!$H$2:$H$200,"P2")) -> 0 | G5: =MAX(0.5,MIN(1.5,1+IF($B5="",0,SUMPRODUCT((SMIX2BT!$D$2:$D$200=$B5)*(SMIX2BT!$H$2:$H$200="P2")*SMIX2BT!$I$2:$I$200*0.01)))) -> 1 | H5: =IF($B5="",0,COUNTIFS(SMIX2BT!$D$2:$D$200,$B5,SMIX2BT!$H$2:$H$200,"P3")) -> 0 | I5: =MAX(0.5,MIN(1.5,1+IF($B5="",0,SUMPRODUCT((SMIX2BT!$D$2:$D$200=$B5)*(SMIX2BT!$H$2:$H$200="P3")*SMIX2BT!$I$2:$I$200*0.01)))) -> 1 | J5: =IF($B5="",0,COUNTIFS(SMIX2BT!$D$2:$D$200,$B5,SMIX2BT!$H$2:$H$200,"P4")) -> 0 | K5: =MAX(0.5,MIN(1.5,1+IF($B5="",0,SUMPRODUCT((SMIX2BT!$D$2:$D$200=$B5)*(SMIX2BT!$H$2:$H$200="P4")*SMIX2BT!$I$2:$I$200*0.01)))) -> 1 | L5: =IF($B5="",0,COUNTIFS(SMIX2BT!$D$2:$D$200,$B5,SMIX2BT!$H$2:$H$200,"P5")) -> 0 | M5: =MAX(0.5,MIN(1.5,1+IF($B5="",0,SUMPRODUCT((SMIX2BT!$D$2:$D$200=$B5)*(SMIX2BT!$H$2:$H$200="P5")*SMIX2BT!$I$2:$I$200*0.01)))) -> 1 | N5: =IF($B5="",0,IFERROR(SUMPRODUCT((SMIX2BT!$D$2:$D$200=$B5)*SMIX2BT!$I$2:$I$200),0)) -> 0 | O5: =D5+F5+H5+J5+L5 -> 0
A6: Aitor Fernández Bernabé | C6: afernandez2@alumnat.copernic.cat | D6: =IF($B6="",0,COUNTIFS(SMIX2BT!$D$2:$D$200,$B6,SMIX2BT!$H$2:$H$200,"P1")) -> 0 | E6: =MAX(0.5,MIN(1.5,1+IF($B6="",0,SUMPRODUCT((SMIX2BT!$D$2:$D$200=$B6)*(SMIX2BT!$H$2:$H$200="P1")*SMIX2BT!$I$2:$I$200*0.01)))) -> 1 | F6: =IF($B6="",0,COUNTIFS(SMIX2BT!$D$2:$D$200,$B6,SMIX2BT!$H$2:$H$200,"P2")) -> 0 | G6: =MAX(0.5,MIN(1.5,1+IF($B6="",0,SUMPRODUCT((SMIX2BT!$D$2:$D$200=$B6)*(SMIX2BT!$H$2:$H$200="P2")*SMIX2BT!$I$2:$I$200*0.01)))) -> 1 | H6: =IF($B6="",0,COUNTIFS(SMIX2BT!$D$2:$D$200,$B6,SMIX2BT!$H$2:$H$200,"P3")) -> 0 | I6: =MAX(0.5,MIN(1.5,1+IF($B6="",0,SUMPRODUCT((SMIX2BT!$D$2:$D$200=$B6)*(SMIX2BT!$H$2:$H$200="P3")*SMIX2BT!$I$2:$I$200*0.01)))) -> 1 | J6: =IF($B6="",0,COUNTIFS(SMIX2BT!$D$2:$D$200,$B6,SMIX2BT!$H$2:$H$200,"P4")) -> 0 | K6: =MAX(0.5,MIN(1.5,1+IF($B6="",0,SUMPRODUCT((SMIX2BT!$D$2:$D$200=$B6)*(SMIX2BT!$H$2:$H$200="P4")*SMIX2BT!$I$2:$I$200*0.01)))) -> 1 | L6: =IF($B6="",0,COUNTIFS(SMIX2BT!$D$2:$D$200,$B6,SMIX2BT!$H$2:$H$200,"P5")) -> 0 | M6: =MAX(0.5,MIN(1.5,1+IF($B6="",0,SUMPRODUCT((SMIX2BT!$D$2:$D$200=$B6)*(SMIX2BT!$H$2:$H$200="P5")*SMIX2BT!$I$2:$I$200*0.01)))) -> 1 | N6: =IF($B6="",0,IFERROR(SUMPRODUCT((SMIX2BT!$D$2:$D$200=$B6)*SMIX2BT!$I$2:$I$200),0)) -> 0 | O6: =D6+F6+H6+J6+L6 -> 0
A7: Albert Gálvez García | C7: agalvez@alumnat.copernic.cat | D7: =IF($B7="",0,COUNTIFS(SMIX2BT!$D$2:$D$200,$B7,SMIX2BT!$H$2:$H$200,"P1")) -> 0 | E7: =MAX(0.5,MIN(1.5,1+IF($B7="",0,SUMPRODUCT((SMIX2BT!$D$2:$D$200=$B7)*(SMIX2BT!$H$2:$H$200="P1")*SMIX2BT!$I$2:$I$200*0.01)))) -> 1 | F7: =IF($B7="",0,COUNTIFS(SMIX2BT!$D$2:$D$200,$B7,SMIX2BT!$H$2:$H$200,"P2")) -> 0 | G7: =MAX(0.5,MIN(1.5,1+IF($B7="",0,SUMPRODUCT((SMIX2BT!$D$2:$D$200=$B7)*(SMIX2BT!$H$2:$H$200="P2")*SMIX2BT!$I$2:$I$200*0.01)))) -> 1 | H7: =IF($B7="",0,COUNTIFS(SMIX2BT!$D$2:$D$200,$B7,SMIX2BT!$H$2:$H$200,"P3")) -> 0 | I7: =MAX(0.5,MIN(1.5,1+IF($B7="",0,SUMPRODUCT((SMIX2BT!$D$2:$D$200=$B7)*(SMIX2BT!$H$2:$H$200="P3")*SMIX2BT!$I$2:$I$200*0.01)))) -> 1 | J7: =IF($B7="",0,COUNTIFS(SMIX2BT!$D$2:$D$200,$B7,SMIX2BT!$H$2:$H$200,"P4")) -> 0 | K7: =MAX(0.5,MIN(1.5,1+IF($B7="",0,SUMPRODUCT((SMIX2BT!$D$2:$D$200=$B7)*(SMIX2BT!$H$2:$H$200="P4")*SMIX2BT!$I$2:$I$200*0.01)))) -> 1 | L7: =IF($B7="",0,COUNTIFS(SMIX2BT!$D$2:$D$200,$B7,SMIX2BT!$H$2:$H$200,"P5")) -> 0 | M7: =MAX(0.5,MIN(1.5,1+IF($B7="",0,SUMPRODUCT((SMIX2BT!$D$2:$D$200=$B7)*(SMIX2BT!$H$2:$H$200="P5")*SMIX2BT!$I$2:$I$200*0.01)))) -> 1 | N7: =IF($B7="",0,IFERROR(SUMPRODUCT((SMIX2BT!$D$2:$D$200=$B7)*SMIX2BT!$I$2:$I$200),0)) -> 0 | O7: =D7+F7+H7+J7+L7 -> 0
A8: Nicolas Francisco González Navarro | C8: nfgonzalez@alumnat.copernic.cat | D8: =IF($B8="",0,COUNTIFS(SMIX2BT!$D$2:$D$200,$B8,SMIX2BT!$H$2:$H$200,"P1")) -> 0 | E8: =MAX(0.5,MIN(1.5,1+IF($B8="",0,SUMPRODUCT((SMIX2BT!$D$2:$D$200=$B8)*(SMIX2BT!$H$2:$H$200="P1")*SMIX2BT!$I$2:$I$200*0.01)))) -> 1 | F8: =IF($B8="",0,COUNTIFS(SMIX2BT!$D$2:$D$200,$B8,SMIX2BT!$H$2:$H$200,"P2")) -> 0 | G8: =MAX(0.5,MIN(1.5,1+IF($B8="",0,SUMPRODUCT((SMIX2BT!$D$2:$D$200=$B8)*(SMIX2BT!$H$2:$H$200="P2")*SMIX2BT!$I$2:$I$200*0.01)))) -> 1 | H8: =IF($B8="",0,COUNTIFS(SMIX2BT!$D$2:$D$200,$B8,SMIX2BT!$H$2:$H$200,"P3")) -> 0 | I8: =MAX(0.5,MIN(1.5,1+IF($B8="",0,SUMPRODUCT((SMIX2BT!$D$2:$D$200=$B8)*(SMIX2BT!$H$2:$H$200="P3")*SMIX2BT!$I$2:$I$200*0.01)))) -> 1 | J8: =IF($B8="",0,COUNTIFS(SMIX2BT!$D$2:$D$200,$B8,SMIX2BT!$H$2:$H$200,"P4")) -> 0 | K8: =MAX(0.5,MIN(1.5,1+IF($B8="",0,SUMPRODUCT((SMIX2BT!$D$2:$D$200=$B8)*(SMIX2BT!$H$2:$H$200="P4")*SMIX2BT!$I$2:$I$200*0.01)))) -> 1 | L8: =IF($B8="",0,COUNTIFS(SMIX2BT!$D$2:$D$200,$B8,SMIX2BT!$H$2:$H$200,"P5")) -> 0 | M8: =MAX(0.5,MIN(1.5,1+IF($B8="",0,SUMPRODUCT((SMIX2BT!$D$2:$D$200=$B8)*(SMIX2BT!$H$2:$H$200="P5")*SMIX2BT!$I$2:$I$200*0.01)))) -> 1 | N8: =IF($B8="",0,IFERROR(SUMPRODUCT((SMIX2BT!$D$2:$D$200=$B8)*SMIX2BT!$I$2:$I$200),0)) -> 0 | O8: =D8+F8+H8+J8+L8 -> 0
A9: Eric Iborra Polo | C9: eiborra@alumnat.copernic.cat | D9: =IF($B9="",0,COUNTIFS(SMIX2BT!$D$2:$D$200,$B9,SMIX2BT!$H$2:$H$200,"P1")) -> 0 | E9: =MAX(0.5,MIN(1.5,1+IF($B9="",0,SUMPRODUCT((SMIX2BT!$D$2:$D$200=$B9)*(SMIX2BT!$H$2:$H$200="P1")*SMIX2BT!$I$2:$I$200*0.01)))) -> 1 | F9: =IF($B9="",0,COUNTIFS(SMIX2BT!$D$2:$D$200,$B9,SMIX2BT!$H$2:$H$200,"P2")) -> 0 | G9: =MAX(0.5,MIN(1.5,1+IF($B9="",0,SUMPRODUCT((SMIX2BT!$D$2:$D$200=$B9)*(SMIX2BT!$H$2:$H$200="P2")*SMIX2BT!$I$2:$I$200*0.01)))) -> 1 | H9: =IF($B9="",0,COUNTIFS(SMIX2BT!$D$2:$D$200,$B9,SMIX2BT!$H$2:$H$200,"P3")) -> 0 | I9: =MAX(0.5,MIN(1.5,1+IF($B9="",0,SUMPRODUCT((SMIX2BT!$D$2:$D$200=$B9)*(SMIX2BT!$H$2:$H$200="P3")*SMIX2BT!$I$2:$I$200*0.01)))) -> 1 | J9: =IF($B9="",0,COUNTIFS(SMIX2BT!$D$2:$D$200,$B9,SMIX2BT!$H$2:$H$200,"P4")) -> 0 | K9: =MAX(0.5,MIN(1.5,1+IF($B9="",0,SUMPRODUCT((SMIX2BT!$D$2:$D$200=$B9)*(SMIX2BT!$H$2:$H$200="P4")*SMIX2BT!$I$2:$I$200*0.01)))) -> 1 | L9: =IF($B9="",0,COUNTIFS(SMIX2BT!$D$2:$D$200,$B9,SMIX2BT!$H$2:$H$200,"P5")) -> 0 | M9: =MAX(0.5,MIN(1.5,1+IF($B9="",0,SUMPRODUCT((SMIX2BT!$D$2:$D$200=$B9)*(SMIX2BT!$H$2:$H$200="P5")*SMIX2BT!$I$2:$I$200*0.01)))) -> 1 | N9: =IF($B9="",0,IFERROR(SUMPRODUCT((SMIX2BT!$D$2:$D$200=$B9)*SMIX2BT!$I$2:$I$200),0)) -> 0 | O9: =D9+F9+H9+J9+L9 -> 0
A10: Hugo Magdaleno Martinez | C10: hmagdaleno@alumnat.copernic.cat | D10: =IF($B10="",0,COUNTIFS(SMIX2BT!$D$2:$D$200,$B10,SMIX2BT!$H$2:$H$200,"P1")) -> 0 | E10: =MAX(0.5,MIN(1.5,1+IF($B10="",0,SUMPRODUCT((SMIX2BT!$D$2:$D$200=$B10)*(SMIX2BT!$H$2:$H$200="P1")*SMIX2BT!$I$2:$I$200*0.01)))) -> 1 | F10: =IF($B10="",0,COUNTIFS(SMIX2BT!$D$2:$D$200,$B10,SMIX2BT!$H$2:$H$200,"P2")) -> 0 | G10: =MAX(0.5,MIN(1.5,1+IF($B10="",0,SUMPRODUCT((SMIX2BT!$D$2:$D$200=$B10)*(SMIX2BT!$H$2:$H$200="P2")*SMIX2BT!$I$2:$I$200*0.01)))) -> 1 | H10: =IF($B10="",0,COUNTIFS(SMIX2BT!$D$2:$D$200,$B10,SMIX2BT!$H$2:$H$200,"P3")) -> 0 | I10: =MAX(0.5,MIN(1.5,1+IF($B10="",0,SUMPRODUCT((SMIX2BT!$D$2:$D$200=$B10)*(SMIX2BT!$H$2:$H$200="P3")*SMIX2BT!$I$2:$I$200*0.01)))) -> 1 | J10: =IF($B10="",0,COUNTIFS(SMIX2BT!$D$2:$D$200,$B10,SMIX2BT!$H$2:$H$200,"P4")) -> 0 | K10: =MAX(0.5,MIN(1.5,1+IF($B10="",0,SUMPRODUCT((SMIX2BT!$D$2:$D$200=$B10)*(SMIX2BT!$H$2:$H$200="P4")*SMIX2BT!$I$2:$I$200*0.01)))) -> 1 | L10: =IF($B10="",0,COUNTIFS(SMIX2BT!$D$2:$D$200,$B10,SMIX2BT!$H$2:$H$200,"P5")) -> 0 | M10: =MAX(0.5,MIN(1.5,1+IF($B10="",0,SUMPRODUCT((SMIX2BT!$D$2:$D$200=$B10)*(SMIX2BT!$H$2:$H$200="P5")*SMIX2BT!$I$2:$I$200*0.01)))) -> 1 | N10: =IF($B10="",0,IFERROR(SUMPRODUCT((SMIX2BT!$D$2:$D$200=$B10)*SMIX2BT!$I$2:$I$200),0)) -> 0 | O10: =D10+F10+H10+J10+L10 -> 0
A11: Iker Magdaleno Martínez | C11: imagdaleno@alumnat.copernic.cat | D11: =IF($B11="",0,COUNTIFS(SMIX2BT!$D$2:$D$200,$B11,SMIX2BT!$H$2:$H$200,"P1")) -> 0 | E11: =MAX(0.5,MIN(1.5,1+IF($B11="",0,SUMPRODUCT((SMIX2BT!$D$2:$D$200=$B11)*(SMIX2BT!$H$2:$H$200="P1")*SMIX2BT!$I$2:$I$200*0.01)))) -> 1 | F11: =IF($B11="",0,COUNTIFS(SMIX2BT!$D$2:$D$200,$B11,SMIX2BT!$H$2:$H$200,"P2")) -> 0 | G11: =MAX(0.5,MIN(1.5,1+IF($B11="",0,SUMPRODUCT((SMIX2BT!$D$2:$D$200=$B11)*(SMIX2BT!$H$2:$H$200="P2")*SMIX2BT!$I$2:$I$200*0.01)))) -> 1 | H11: =IF($B11="",0,COUNTIFS(SMIX2BT!$D$2:$D$200,$B11,SMIX2BT!$H$2:$H$200,"P3")) -> 0 | I11: =MAX(0.5,MIN(1.5,1+IF($B11="",0,SUMPRODUCT((SMIX2BT!$D$2:$D$200=$B11)*(SMIX2BT!$H$2:$H$200="P3")*SMIX2BT!$I$2:$I$200*0.01)))) -> 1 | J11: =IF($B11="",0,COUNTIFS(SMIX2BT!$D$2:$D$200,$B11,SMIX2BT!$H$2:$H$200,"P4")) -> 0 | K11: =MAX(0.5,MIN(1.5,1+IF($B11="",0,SUMPRODUCT((SMIX2BT!$D$2:$D$200=$B11)*(SMIX2BT!$H$2:$H$200="P4")*SMIX2BT!$I$2:$I$200*0.01)))) -> 1 | L11: =IF($B11="",0,COUNTIFS(SMIX2BT!$D$2:$D$200,$B11,SMIX2BT!$H$2:$H$200,"P5")) -> 0 | M11: =MAX(0.5,MIN(1.5,1+IF($B11="",0,SUMPRODUCT((SMIX2BT!$D$2:$D$200=$B11)*(SMIX2BT!$H$2:$H$200="P5")*SMIX2BT!$I$2:$I$200*0.01)))) -> 1 | N11: =IF($B11="",0,IFERROR(SUMPRODUCT((SMIX2BT!$D$2:$D$200=$B11)*SMIX2BT!$I$2:$I$200),0)) -> 0 | O11: =D11+F11+H11+J11+L11 -> 0
A12: Izan Malagón Martinez | C12: imalagon@alumnat.copernic.cat | D12: =IF($B12="",0,COUNTIFS(SMIX2BT!$D$2:$D$200,$B12,SMIX2BT!$H$2:$H$200,"P1")) -> 0 | E12: =MAX(0.5,MIN(1.5,1+IF($B12="",0,SUMPRODUCT((SMIX2BT!$D$2:$D$200=$B12)*(SMIX2BT!$H$2:$H$200="P1")*SMIX2BT!$I$2:$I$200*0.01)))) -> 1 | F12: =IF($B12="",0,COUNTIFS(SMIX2BT!$D$2:$D$200,$B12,SMIX2BT!$H$2:$H$200,"P2")) -> 0 | G12: =MAX(0.5,MIN(1.5,1+IF($B12="",0,SUMPRODUCT((SMIX2BT!$D$2:$D$200=$B12)*(SMIX2BT!$H$2:$H$200="P2")*SMIX2BT!$I$2:$I$200*0.01)))) -> 1 | H12: =IF($B12="",0,COUNTIFS(SMIX2BT!$D$2:$D$200,$B12,SMIX2BT!$H$2:$H$200,"P3")) -> 0 | I12: =MAX(0.5,MIN(1.5,1+IF($B12="",0,SUMPRODUCT((SMIX2BT!$D$2:$D$200=$B12)*(SMIX2BT!$H$2:$H$200="P3")*SMIX2BT!$I$2:$I$200*0.01)))) -> 1 | J12: =IF($B12="",0,COUNTIFS(SMIX2BT!$D$2:$D$200,$B12,SMIX2BT!$H$2:$H$200,"P4")) -> 0 | K12: =MAX(0.5,MIN(1.5,1+IF($B12="",0,SUMPRODUCT((SMIX2BT!$D$2:$D$200=$B12)*(SMIX2BT!$H$2:$H$200="P4")*SMIX2BT!$I$2:$I$200*0.01)))) -> 1 | L12: =IF($B12="",0,COUNTIFS(SMIX2BT!$D$2:$D$200,$B12,SMIX2BT!$H$2:$H$200,"P5")) -> 0 | M12: =MAX(0.5,MIN(1.5,1+IF($B12="",0,SUMPRODUCT((SMIX2BT!$D$2:$D$200=$B12)*(SMIX2BT!$H$2:$H$200="P5")*SMIX2BT!$I$2:$I$200*0.01)))) -> 1 | N12: =IF($B12="",0,IFERROR(SUMPRODUCT((SMIX2BT!$D$2:$D$200=$B12)*SMIX2BT!$I$2:$I$200),0)) -> 0 | O12: =D12+F12+H12+J12+L12 -> 0
A13: Alexis Martínez Vaca | C13: amartinez5@alumnat.copernic.cat | D13: =IF($B13="",0,COUNTIFS(SMIX2BT!$D$2:$D$200,$B13,SMIX2BT!$H$2:$H$200,"P1")) -> 0 | E13: =MAX(0.5,MIN(1.5,1+IF($B13="",0,SUMPRODUCT((SMIX2BT!$D$2:$D$200=$B13)*(SMIX2BT!$H$2:$H$200="P1")*SMIX2BT!$I$2:$I$200*0.01)))) -> 1 | F13: =IF($B13="",0,COUNTIFS(SMIX2BT!$D$2:$D$200,$B13,SMIX2BT!$H$2:$H$200,"P2")) -> 0 | G13: =MAX(0.5,MIN(1.5,1+IF($B13="",0,SUMPRODUCT((SMIX2BT!$D$2:$D$200=$B13)*(SMIX2BT!$H$2:$H$200="P2")*SMIX2BT!$I$2:$I$200*0.01)))) -> 1 | H13: =IF($B13="",0,COUNTIFS(SMIX2BT!$D$2:$D$200,$B13,SMIX2BT!$H$2:$H$200,"P3")) -> 0 | I13: =MAX(0.5,MIN(1.5,1+IF($B13="",0,SUMPRODUCT((SMIX2BT!$D$2:$D$200=$B13)*(SMIX2BT!$H$2:$H$200="P3")*SMIX2BT!$I$2:$I$200*0.01)))) -> 1 | J13: =IF($B13="",0,COUNTIFS(SMIX2BT!$D$2:$D$200,$B13,SMIX2BT!$H$2:$H$200,"P4")) -> 0 | K13: =MAX(0.5,MIN(1.5,1+IF($B13="",0,SUMPRODUCT((SMIX2BT!$D$2:$D$200=$B13)*(SMIX2BT!$H$2:$H$200="P4")*SMIX2BT!$I$2:$I$200*0.01)))) -> 1 | L13: =IF($B13="",0,COUNTIFS(SMIX2BT!$D$2:$D$200,$B13,SMIX2BT!$H$2:$H$200,"P5")) -> 0 | M13: =MAX(0.5,MIN(1.5,1+IF($B13="",0,SUMPRODUCT((SMIX2BT!$D$2:$D$200=$B13)*(SMIX2BT!$H$2:$H$200="P5")*SMIX2BT!$I$2:$I$200*0.01)))) -> 1 | N13: =IF($B13="",0,IFERROR(SUMPRODUCT((SMIX2BT!$D$2:$D$200=$B13)*SMIX2BT!$I$2:$I$200),0)) -> 0 | O13: =D13+F13+H13+J13+L13 -> 0
